Workbook

Sheet 2025年一季度指标
B1: 消耗 | F1: 门店按自然月下指标，按自然月考核 | O1: 门店按自然月下指标，按自然月考核 | X1: 门店按自然月下指标，按自然月考核 | AE1: Q1指标覆盖时间：自然月1/1-3/31
B2: YesSkin | D2: 2024年1月实际 | F2: 2025年1月指标 | H2: 2025年1月实际（自然月） | K2: YesSkin | M2: 2024年2月实际 | O2: 2025年2月指标 | Q2: 2025 年2月实际（自然月） | T2: YesSkin | V2: 2024年3月实际 | X2: 2025年3月指标 | Z2: 2025 年3月实际（自然月） | AC2: 2024年一季度 | AE2: 2025年一季度指标 | AG2: 2025年一季度实际
D3: 1月消耗 | E3: 增幅 | F3: 1月消耗 | G3: 增幅 | H3: 1月消耗 | I3: Evl% | J3: 指标达成率 | M3: 2月消耗 | N3: 增幅 | O3: 2月消耗 | P3: 增幅 | Q3: 2月消耗 | R3: 增幅 | S3: 指标达成率 | V3: 3月消耗 | W3: 增幅 | X3: 3月消耗 | Y3: 增幅 | Z3: 3月消耗 | AA3: 增幅 | AB3: 指标达成率 | AC3: 一季度消耗 | AD3: 增幅 | AE3: 一季度消耗 | AF3: 增幅 | AG3: 一季度消耗 | AH3: 增幅 | AI3: 指标达成率
B4: 全国合计 Total | D4: 12147.977 | E4: 0.5516304 | F4: =F5+F12 -> 12642.62 | G4: =F4/D4-1 -> 0.040718087 | H4: =H5+H12 -> 9739.9655 | I4: =H4/D4-1 -> -0.19822328 | J4: =H4/F4 -> 0.77040721 | K4: National Total | M4: 6161.8072 | N4: -0.47726732 | O4: =O5+O12 -> 7348.9939 | P4: =O4/M4-1 -> 0.1926686 | Q4: =Q5+Q12 -> 5659.6653 | R4: =Q4/M4-1 -> -0.081492627 | S4: =Q4/O4 -> 0.77012791 | T4: National Total | V4: 10167.27 | W4: -0.15920278 | X4: =X5+X12 -> 11820 | Y4: =X4/V4-1 -> 0.16255394 | Z4: =Z5+Z12 -> 8868.0327 | AA4: =Z4/V4-1 -> -0.12778627 | AB4: =Z4/X4 -> 0.75025657 | AC4: =AC5+AC12 -> 28477.055 | AD4: -0.10193279 | AE4: =AE5+AE12 -> 31811.614 | AF4: =AE4/AC4-1 -> 0.11709634 | AG4: =AG5+AG12 -> 24267.663 | AH4: =AG4/AC4-1 -> -0.14781695 | AI4: =AG4/AE4 -> 0.76285547
B5: 杭州合计 | D5: 9814.654 | E5: 0.68538143 | F5: =F6+F7+F10+F11 -> 10042.62 | G5: =F5/D5-1 -> 0.023227082 | H5: =H6+H7+H10+H11 -> 8162.1414 | I5: =H5/D5-1 -> -0.16837197 | J5: =H5/F5 -> 0.81275022 | K5: HZ Total | M5: 4669.0343 | N5: -0.51345122 | O5: =O6+O7+O10+O11 -> 5448.9939 | P5: =O5/M5-1 -> 0.16704946 | Q5: =Q6+Q7+Q10+Q11 -> 4345.9196 | R5: =Q5/M5-1 -> -0.069203739 | S5: =Q5/O5 -> 0.79756368 | T5: HZ Total | V5: 7898.4281 | W5: -0.2070436 | X5: =X6+X7+X10+X11 -> 8240 | Y5: =X5/V5-1 -> 0.043245559 | Z5: =Z6+Z7+Z10+Z11 -> 7246.5618 | AA5: =Z5/V5-1 -> -0.082531142 | AB5: =Z5/X5 -> 0.87943711 | AC5: =AC6+AC7+AC10+AC11 -> 22382.116 | AD5: -0.036953699 | AE5: =AE6+AE7+AE10+AE11 -> 23731.614 | AF5: =AE5/AC5-1 -> 0.060293555 | AG5: =AG6+AG7+AG10+AG11 -> 19754.623 | AH5: =AG5/AC5-1 -> -0.11739254 | AI5: =AG5/AE5 -> 0.83241802
B6: 杭州时尚 | C6: HZ Fashion | D6: 3902.3817 | E6: 0.61484557 | F6: 4292.6198 | G6: =F6/D6-1 -> 0.1 | H6: 4060.5213 | I6: =H6/D6-1 -> 0.040523889 | J6: =H6/F6 -> 0.94593081 | K6: 杭州时尚 | L6: HZ Fashion | M6: 2087.1025 | N6: -0.44737158 | O6: 2366.2033 | P6: =O6/M6-1 -> 0.13372645 | Q6: 2241.262 | R6: =Q6/M6-1 -> 0.073862938 | S6: =Q6/O6 -> 0.94719757 | T6: 杭州时尚 | U6: HZ Fashion | V6: 3132.6627 | W6: -0.27621727 | X6: 3500 | Y6: =X6/V6-1 -> 0.11726039 | Z6: 3939.8883 | AA6: =Z6/V6-1 -> 0.25768031 | AB6: =Z6/X6 -> 1.1256824 | AC6: =D6+M6+V6 -> 9122.1469 | AD6: -0.13299369 | AE6: =F6+O6+X6 -> 10158.823 | AF6: =AE6/AC6-1 -> 0.11364389 | AG6: =H6+Q6+Z6 -> 10241.672 | AH6: =AG6/AC6-1 -> 0.12272601 | AI6: =AG6/AE6 -> 1.0081553
B7: 杭州悦容（西子） | C7: HZ Ruerong | D7: 4005.004 | E7: 0.61238877 | F7: 3900 | G7: =F7/D7-1 -> -0.026218191 | H7: 3041.3045 | I7: =H7/D7-1 -> -0.24062385 | J7: =H7/F7 -> 0.77982166 | K7: 杭州悦容（西子） | L7: HZ Ruerong | M7: 1826.4125 | N7: -0.53594912 | O7: 2043.7906 | P7: =O7/M7-1 -> 0.11901917 | Q7: 1406.4577 | R7: =Q7/M7-1 -> -0.2299343 | S7: =Q7/O7 -> 0.68816132 | T7: 杭州悦容（西子） | U7: HZ Ruerong | V7: 3254.1744 | W7: -0.17509327 | X7: 3200 | Y7: =X7/V7-1 -> -0.016647669 | Z7: 2236.1863 | AA7: =Z7/V7-1 -> -0.31282531 | AB7: =Z7/X7 -> 0.69880822 | AC7: =D7+M7+V7 -> 9085.5909 | AD7: -0.12340142 | AE7: =F7+O7+X7 -> 9143.7906 | AF7: =AE7/AC7-1 -> 0.0064057167 | AG7: =H7+Q7+Z7 -> 6683.9485 | AH7: =AG7/AC7-1 -> -0.26433531 | AI7: =AG7/AE7 -> 0.73098223
B8: 吴慧玲 | D8: 721.3898 | E8: 0.49588719 | F8: 300 | G8: =F8/D8-1 -> -0.58413607 | H8: 408.32073 | K8: 吴慧玲 | M8: 461.8415 | N8: -0.55601406 | O8: 300 | P8: =O8/M8-1 -> -0.3504265 | Q8: 319.58455 | T8: 吴慧玲 | V8: 845.60048 | W8: -0.061513785 | X8: 300 | Z8: 518.40341 | AC8: =D8+M8+V8 -> 2028.8318 | AD8: -0.16284751 | AE8: =F8+O8+X8 -> 900 | AG8: =H8+Q8+Z8 -> 1246.3087
B9: 杭州悦容（西子） 不含吴慧玲 | D9: 3283.6142 | E9: 0.64045704 | F9: =F7-F8 -> 3600 | G9: =F9/D9-1 -> 0.096352928 | H9: =H7-H8 -> 2632.9838 | I9: =H9/D9-1 -> -0.1981446 | J9: =H9/F9 -> 0.73138438 | K9: 杭州悦容（西子） 不含吴慧玲 | M9: 1364.571 | N9: -0.52874094 | O9: =O7-O8 -> 1743.7906 | P9: =O9/M9-1 -> 0.27790389 | Q9: =Q7-Q8 -> 1086.8731 | R9: =Q9/M9-1 -> -0.20350566 | S9: =Q9/O9 -> 0.62328188 | T9: 杭州悦容（西子） 不含吴慧玲 | V9: 2408.5739 | W9: -0.20871426 | X9: =X7-X8 -> 2900 | Y9: =X9/V9-1 -> 0.20403196 | Z9: =Z7-Z8 -> 1717.7829 | AA9: =Z9/V9-1 -> -0.286805 | AB9: =Z9/X9 -> 0.59233893 | AC9: =D9+M9+V9 -> 7056.7591 | AD9: -0.11136314 | AE9: =F9+O9+X9 -> 8243.7906 | AG9: =H9+Q9+Z9 -> 5437.6398 | AH9: =AG9/AC9-1 -> -0.22944235 | AI9: =AG9/AE9 -> 0.6596043
B10: 杭州素颜丰潭（城西） | C10: HZ Suyan Fengtan(West) | D10: 768.92637 | E10: 0.71323698 | F10: 750 | G10: =F10/D10-1 -> -0.024614021 | H10: 542.31623 | I10: =H10/D10-1 -> -0.2947098 | J10: =H10/F10 -> 0.72308831 | K10: 杭州素颜丰潭（城西） | L10: HZ Suyan Fengtan(West) | M10: 254.32567 | N10: -0.70931699 | O10: 359 | P10: =O10/M10-1 -> 0.41157595 | Q10: 136.75783 | R10: =Q10/M10-1 -> -0.4622728 | S10: =Q10/O10 -> 0.38094103 | T10: 杭州素颜丰潭（城西） | U10: HZ Suyan Fengtan(West) | V10: 648.66205 | W10: -0.25462282 | X10: 650 | Y10: =X10/V10-1 -> 0.0020626303 | Z10: 369.16871 | AA10: =Z10/V10-1 -> -0.43087666 | AB10: =Z10/X10 -> 0.56795186 | AC10: =D10+M10+V10 -> 1671.9141 | AD10: -0.23795594 | AE10: =F10+O10+X10 -> 1759 | AF10: =AE10/AC10-1 -> 0.052087551 | AG10: =H10+Q10+Z10 -> 1048.2428 | AH10: =AG10/AC10-1 -> -0.37302833 | AI10: =AG10/AE10 -> 0.59593108
B11: 杭州新芽（万通） | C11: HZ Xinya | D11: 1138.3421 | E11: 1.4009266 | F11: 1100 | G11: =F11/D11-1 -> -0.033682371 | H11: 517.99938 | I11: =H11/D11-1 -> -0.54495279 | J11: =H11/F11 -> 0.47090853 | K11: 杭州新芽（万通） | L11: HZ Xinya | M11: 501.19359 | N11: -0.50318859 | O11: 680 | P11: =O11/M11-1 -> 0.35676117 | Q11: 561.44216 | R11: =Q11/M11-1 -> 0.12021018 | S11: =Q11/O11 -> 0.82565024 | T11: 杭州新芽（万通） | U11: HZ Xinya | V11: 862.92884 | W11: 0.055690944 | X11: 890 | Y11: =X11/V11-1 -> 0.031371254 | Z11: 701.3185 | AA11: =Z11/V11-1 -> -0.18728119 | AB11: =Z11/X11 -> 0.78799831 | AC11: =D11+M11+V11 -> 2502.4645 | AD11: 0.087860868 | AE11: =F11+O11+X11 -> 2670 | AF11: =AE11/AC11-1 -> 0.066948207 | AG11: =H11+Q11+Z11 -> 1780.76 | AH11: =AG11/AC11-1 -> -0.28839748 | AI11: =AG11/AE11 -> 0.66695133
B12: 杭外合计 | D12: 2333.3234 | E12: 0.16330716 | F12: =F13+F14 -> 2600 | G12: =F12/D12-1 -> 0.11429047 | H12: =H13+H14 -> 1577.824 | I12: =H12/D12-1 -> -0.32378681 | J12: =H12/F12 -> 0.6068554 | K12: outsize HZ Total | M12: 1492.7729 | N12: -0.31882033 | O12: =O13+O14 -> 1900 | P12: =O12/M12-1 -> 0.27279911 | Q12: =Q13+Q14 -> 1313.7457 | R12: =Q12/M12-1 -> -0.11992931 | S12: =Q12/O12 -> 0.69144508 | T12: outsize HZ Total | V12: 2268.8421 | W12: 0.064343529 | X12: =X13+X14 -> 3580 | Y12: =X12/V12-1 -> 0.57789739 | Z12: =Z13+Z14 -> 1621.4709 | AA12: =Z12/V12-1 -> -0.28533109 | AB12: =Z12/X12 -> 0.45292483 | AC12: =AC13+AC14 -> 6094.9383 | AD12: -0.036967475 | AE12: =AE13+AE14 -> 8080 | AF12: =AE12/AC12-1 -> 0.3256902 | AG12: =AG13+AG14 -> 4513.0406 | AH12: =AG12/AC12-1 -> -0.25954286 | AI12: =AG12/AE12 -> 0.55854463
B13: 上海诊所 | C13: SH Clinic | D13: 1515.9835 | E13: -0.074505842 | F13: 1800 | G13: =F13/D13-1 -> 0.18734799 | H13: 863.47934 | I13: =H13/D13-1 -> -0.43041641 | J13: =H13/F13 -> 0.47971074 | K13: 上海诊所 | L13: SH Clinic | M13: 1122.5704 | N13: -0.29681134 | O13: 1300 | P13: =O13/M13-1 -> 0.15805653 | Q13: 973.49416 | R13: =Q13/M13-1 -> -0.13279903 | S13: =Q13/O13 -> 0.74884166 | T13: 上海诊所 | U13: SH Clinic | V13: 1695.7907 | W13: 0.17230931 | X13: 3000 | Y13: =X13/V13-1 -> 0.76908621 | Z13: 1048.8925 | AA13: =Z13/V13-1 -> -0.38147292 | AB13: =Z13/X13 -> 0.34963083 | AC13: =D13+M13+V13 -> 4334.3447 | AD13: -0.074048853 | AE13: =F13+O13+X13 -> 6100 | AF13: =AE13/AC13-1 -> 0.40736385 | AG13: =H13+Q13+Z13 -> 2885.866 | AH13: =AG13/AC13-1 -> -0.33418632 | AI13: =AG13/AE13 -> 0.47309279
B14: 苏州诊所 | C14: Suzhuo Clinic | D14: 817.33985 | E14: 1.2225953 | F14: 800 | G14: =F14/D14-1 -> -0.021214982 | H14: 714.34471 | I14: =H14/D14-1 -> -0.12601262 | J14: =H14/F14 -> 0.89293089 | K14: 苏州诊所 | L14: Suzhuo Clinic | M14: 370.20246 | N14: -0.37786582 | O14: 600 | P14: =O14/M14-1 -> 0.62073477 | Q14: 340.2515 | R14: =Q14/M14-1 -> -0.080904271 | S14: =Q14/O14 -> 0.56708583 | T14: 苏州诊所 | U14: Suzhuo Clinic | V14: 573.05135 | W14: -0.16360388 | X14: 580 | Y14: =X14/V14-1 -> 0.012125702 | Z14: 572.5784 | AA14: =Z14/V14-1 -> -0.00082531871 | AB14: =Z14/X14 -> 0.98720414 | AC14: =D14+M14+V14 -> 1760.5937 | AD14: 0.068362166 | AE14: =F14+O14+X14 -> 1980 | AF14: =AE14/AC14-1 -> 0.12462066 | AG14: =H14+Q14+Z14 -> 1627.1746 | AH14: =AG14/AC14-1 -> -0.075780717 | AI14: =AG14/AE14 -> 0.82180536
B15: 杭州不含吴慧玲 | D15: 9093.2642 | E15: 0.70249072 | F15: =F5-F8 -> 9742.6198 | G15: =F15/D15-1 -> 0.071410613 | H15: =H5-H8 -> 7753.8207 | I15: =H15/D15-1 -> -0.14730063 | J15: =H15/F15 -> 0.79586609 | K15: 杭州不含吴慧玲 | M15: 4207.1928 | N15: -0.50827655 | O15: =O5-O8 -> 5148.9939 | P15: =O15/M15-1 -> 0.223855 | Q15: =Q5-Q8 -> 4026.3351 | R15: =Q15/M15-1 -> -0.042987733 | S15: =Q15/O15 -> 0.7819654 | T15: 杭州不含吴慧玲 | V15: 7052.8276 | W15: -0.22151715 | X15: =X5-X8 -> 7940 | Y15: =X15/V15-1 -> 0.12578961 | Z15: =Z5-Z8 -> 6728.1584 | AA15: =Z15/V15-1 -> -0.046033909 | AB15: =Z15/X15 -> 0.84737511 | AC15: =AC5-AC8 -> 20353.285 | AD15: -0.11341227 | AE15: =AE5-AE8 -> 22831.614 | AF15: =AE15/AC15-1 -> 0.12176556 | AG15: =AG5-AG8 -> 18508.314 | AH15: =AG15/AC15-1 -> -0.090647307 | AI15: =AG15/AE15 -> 0.81064415
B16: 全国不含吴慧玲 | D16: 11426.588 | E16: 0.55528936 | F16: =F4-F8 -> 12342.62 | G16: =F16/D16-1 -> 0.080166733 | H16: =H4-H8 -> 9331.6448 | I16: =H16/D16-1 -> -0.18333933 | J16: =H16/F16 -> 0.75605057 | K16: 全国不含吴慧玲 | M16: 5699.9657 | N16: -0.46964565 | O16: =O4-O8 -> 7048.9939 | P16: =O16/M16-1 -> 0.23667305 | Q16: =Q4-Q8 -> 5340.0807 | R16: =Q16/M16-1 -> -0.063138082 | S16: =Q16/O16 -> 0.75756637 | T16: 全国不含吴慧玲 | V16: 9321.6697 | W16: -0.16706778 | X16: =X4-X8 -> 11520 | Y16: =X16/V16-1 -> 0.23583011 | Z16: =Z4-Z8 -> 8349.6292 | AA16: =Z16/V16-1 -> -0.1042775 | AB16: =Z16/X16 -> 0.72479421 | AC16: =AC4-AC8 -> 26448.223 | AD16: -0.096891906 | AE16: =AE4-AE8 -> 30911.614 | AF16: =AE16/AC16-1 -> 0.16875957 | AG16: =AG4-AG8 -> 23021.355 | AH16: =AG16/AC16-1 -> -0.12956894 | AI16: =AG16/AE16 -> 0.74474775
B20: YesSkin | D20: 2024年1+2月实际 | F20: 2025年1+2月指标 | H20: 2025年1+2月实际
D21: 1月+2月消耗 | E21: 增幅 | F21: 1月+2月消耗 | G21: 增幅 | H21: 1月+2月消耗 | I21: 增幅 | J21: 指标达成率
B22: National Total | D22: =D23+D30 -> 18309.785 | E22: -0.066629854 | F22: =F23+F30 -> 19991.614 | G22: =F22/D22-1 -> 0.09185412 | H22: =H23+H30 -> 15399.631 | I22: =H22/D22-1 -> -0.15893982 | J22: =H22/F22 -> 0.77030454
B23: HZ Total | D23: =D24+D25+D28+D29 -> 14483.688 | E23: -0.060698239 | F23: =F24+F25+F28+F29 -> 15491.614 | G23: =F23/D23-1 -> 0.069590383 | H23: =H24+H25+H28+H29 -> 12508.061 | I23: =H23/D23-1 -> -0.1364036 | J23: =H23/F23 -> 0.80740853
B24: 杭州时尚 | C24: HZ Fashion | D24: =D6+M6 -> 5989.4841 | E24: -0.032901236 | F24: =F6+O6 -> 6658.8231 | G24: =F24/D24-1 -> 0.11175236 | H24: =H6+Q6 -> 6301.7833 | I24: =H24/D24-1 -> 0.052141252 | J24: =H24/F24 -> 0.94638095
B25: 杭州悦容（西子） | C25: HZ Ruerong | D25: =D7+M7 -> 5831.4165 | E25: -0.091636806 | F25: =F7+O7 -> 5943.7906 | G25: =F25/D25-1 -> 0.019270471 | H25: =H7+Q7 -> 4447.7621 | I25: =H25/D25-1 -> -0.23727586 | J25: =H25/F25 -> 0.74830397
B26: 吴慧玲 | D26: =D8+M8 -> 1183.2313 | E26: -0.22281887 | F26: =F8+O8 -> 600 | G26: =F26/D26-1 -> -0.49291402 | H26: =H8+Q8 -> 727.90528
B27: 杭州悦容（西子） 不含吴慧玲 | D27: =D25-D26 -> 4648.1852 | E27: -0.050854553 | F27: =F9+O9 -> 5343.7906 | G27: =F27/D27-1 -> 0.14965097 | H27: =H9+Q9 -> 3719.8569 | J27: =H27/F27 -> 0.69610827
B28: 杭州素颜丰潭（城西） | C28: HZ Suyan Fengtan(West) | D28: =D10+M10 -> 1023.252 | E28: -0.22699888 | F28: =F10+O10 -> 1109 | G28: =F28/D28-1 -> 0.083799452 | H28: =H10+Q10 -> 679.07406 | I28: =H28/D28-1 -> -0.33635699 | J28: =H28/F28 -> 0.61233008
B29: 杭州新芽（万通） | C29: HZ Xinya | D29: =D11+M11 -> 1639.5356 | E29: 0.10559307 | F29: =F11+O11 -> 1780 | G29: =F29/D29-1 -> 0.085673251 | H29: =H11+Q11 -> 1079.4415 | I29: =H29/D29-1 -> -0.34161752 | J29: =H29/F29 -> 0.60642783
B30: outsize HZ Total | D30: =D31+D32 -> 3826.0963 | E30: -0.088421263 | F30: =F31+F32 -> 4500 | G30: =F30/D30-1 -> 0.1761335 | H30: =H31+H32 -> 2891.5697 | I30: =H30/D30-1 -> -0.24425066 | J30: =H30/F30 -> 0.64257105
B31: 上海诊所 | C31: SH Clinic | D31: =D13+M13 -> 2638.5539 | E31: -0.18422809 | F31: =F13+O13 -> 3100 | G31: =F31/D31-1 -> 0.17488596 | H31: =H13+Q13 -> 1836.9735 | I31: =H31/D31-1 -> -0.30379536 | J31: =H31/F31 -> 0.5925721
B32: 苏州诊所 | C32: Suzhuo Clinic | D32: =D14+M14 -> 1187.5423 | E32: 0.23343391 | F32: =F14+O14 -> 1400 | G32: =F32/D32-1 -> 0.17890536 | H32: =H14+Q14 -> 1054.5962 | I32: =H32/D32-1 -> -0.11195062 | J32: =H32/F32 -> 0.75328301
B33: 杭州不含吴慧玲 | D33: =D23-D26 -> 13300.457 | E33: -0.042937567 | F33: =F23-F26 -> 14891.614 | G33: =F33/D33-1 -> 0.11963173 | H33: =H23-H26 -> 11780.156 | I33: =H33/D33-1 -> -0.11430443 | J33: =H33/F33 -> 0.79105972
B34: 全国不含吴慧玲 | D34: =D22-D26 -> 17126.553 | E34: -0.05348808 | F34: =F22-F26 -> 19391.614 | G34: =F34/D34-1 -> 0.13225431 | H34: =H22-H26 -> 14671.726 | I34: =H34/D34-1 -> -0.14333461 | J34: =H34/F34 -> 0.75660158
B37: 开单 | F37: 门店按自然月下指标，按自然月考核 | O37: 门店按自然月下指标，按自然月考核 | X37: 门店按自然月下指标，按自然月考核 | AE37: Q1指标覆盖时间：自然月1/1-3/31
B38: YesSkin | D38: 2024年1月实际 | F38: 2025年1月指标 | H38: 2025年1月实际（自然月） | K38: YesSkin | M38: 2024年2月实际 | O38: 2025年2月指标 | Q38: 2025 年2月实际（自然月） | T38: YesSkin | V38: 2024年3月实际 | X38: 2025年3月指标 | Z38: 2025 年3月实际（自然月） | AC38: 2024年一季度 | AE38: 2025年一季度指标 | AG38: 2025年一季度实际
D39: 1月开单 | E39: 增幅 | F39: 1月开单 | G39: 增幅 | H39: 1月开单 | I39: Evl% | J39: 指标达成率 | M39: 2月开单 | N39: 增幅 | O39: 2月开单 | P39: 增幅 | Q39: 2月开单 | R39: 增幅 | S39: 指标达成率 | V39: 3月开单 | W39: 增幅 | X39: 3月开单 | Y39: 增幅 | Z39: 3月开单 | AA39: 增幅 | AB39: 指标达成率 | AC39: 一季度开单 | AD39: 增幅 | AE39: 一季度开单 | AF39: 增幅 | AG39: 一季度开单 | AH39: 增幅 | AI39: 指标达成率
B40: National Total | D40: 11301.077 | E40: 0.53917397 | F40: =F41+F48 -> 12369.505 | G40: =F40/D40-1 -> 0.094542217 | H40: =H41+H48 -> 8246.5317 | I40: =H40/D40-1 -> -0.27028796 | J40: =H40/F40 -> 0.66668241 | K40: National Total | M40: 5557.7692 | N40: -0.5174317 | O40: =O41+O48 -> 7520 | P40: =O40/M40-1 -> 0.35306087 | Q40: =Q41+Q48 -> 5233.1138 | R40: =Q40/M40-1 -> -0.058414704 | S40: =Q40/O40 -> 0.69589279 | T40: National Total | V40: 10649.162 | W40: -0.1003406 | X40: =X41+X48 -> 12710 | Y40: =X40/V40-1 -> 0.1935211 | Z40: =Z41+Z48 -> 9703.6267 | AA40: =Z40/V40-1 -> -0.088789683 | AB40: =Z40/X40 -> 0.76346394 | AC40: =AC41+AC48 -> 27508.008 | AD40: -0.10386404 | AE40: =AE41+AE48 -> 32599.505 | AF40: =AE40/AC40-1 -> 0.18509145 | AG40: =AG41+AG48 -> 23183.272 | AH40: =AG40/AC40-1 -> -0.15721735 | AI40: =AG40/AE40 -> 0.7111541
B41: HZ Total | D41: 8715.3363 | E41: 0.74902398 | F41: =F42+F43+F46+F47 -> 8619.5054 | G41: =F41/D41-1 -> -0.010995658 | H41: =H42+H43+H46+H47 -> 7157.7455 | I41: =H41/D41-1 -> -0.17871838 | J41: =H41/F41 -> 0.83041255 | K41: HZ Total | M41: 4149.6965 | N41: -0.55789942 | O41: =O42+O43+O46+O47 -> 5520 | P41: =O41/M41-1 -> 0.33021777 | Q41: =Q42+Q43+Q46+Q47 -> 4090.7255 | R41: =Q41/M41-1 -> -0.014210907 | S41: =Q41/O41 -> 0.74107347 | T41: HZ Total | V41: 8309.4951 | W41: -0.15423033 | X41: =X42+X43+X46+X47 -> 8210 | Y41: =X41/V41-1 -> -0.011973667 | Z41: =Z42+Z43+Z46+Z47 -> 7914.1764 | AA41: =Z41/V41-1 -> -0.047574334 | AB41: =Z41/X41 -> 0.9639679 | AC41: =AC42+AC43+AC46+AC47 -> 21174.528 | AD41: -0.12480476 | AE41: =AE42+AE43+AE46+AE47 -> 22349.505 | AF41: =AE41/AC41-1 -> 0.05549014 | AG41: =AG42+AG43+AG46+AG47 -> 19162.647 | AH41: =AG41/AC41-1 -> -0.095014183 | AI41: =AG41/AE41 -> 0.85740812
B42: 杭州时尚 | C42: HZ Fashion | D42: 3504.3619 | E42: 0.94450702 | F42: =F6*0.88 -> 3777.5054 | G42: =F42/D42-1 -> 0.077943885 | H42: 3274.2316 | I42: =H42/D42-1 -> -0.065669662 | J42: =H42/F42 -> 0.86677085 | K42: 杭州时尚 | L42: HZ Fashion | M42: 1438.4729 | N42: -0.59335344 | O42: 2100 | P42: =O42/M42-1 -> 0.45988154 | Q42: 1802.1403 | R42: =Q42/M42-1 -> 0.25281492 | S42: =Q42/O42 -> 0.85816204 | T42: 杭州时尚 | U42: HZ Fashion | V42: 3325.9134 | W42: -0.22870102 | X42: 3400 | Y42: =X42/V42-1 -> 0.022275562 | Z42: 3278.5332 | AA42: =Z42/V42-1 -> -0.01424578 | AB42: =Z42/X42 -> 0.96427446 | AC42: =D42+M42+V42 -> 8268.7482 | AD42: -0.14328425 | AE42: =F42+O42+X42 -> 9277.5054 | AF42: =AE42/AC42-1 -> 0.12199637 | AG42: =H42+Q42+Z42 -> 8354.9051 | AH42: =AG42/AC42-1 -> 0.010419584 | AI42: =AG42/AE42 -> 0.90055513
B43: 杭州悦容（西子） | C43: HZ Ruerong | D43: 3465.8445 | E43: 0.59718752 | F43: =F44+F45 -> 3100 | G43: =F43/D43-1 -> -0.10555711 | H43: 2576.0682 | I43: =H43/D43-1 -> -0.25672713 | J43: =H43/F43 -> 0.83098975 | K43: 杭州悦容（西子） | L43: HZ Ruerong | M43: 2016.9546 | N43: -0.49632134 | O43: =O44+O45 -> 2400 | P43: =O43/M43-1 -> 0.18991277 | Q43: 1419.5293 | R43: =Q43/M43-1 -> -0.29620166 | S43: =Q43/O43 -> 0.59147053 | T43: 杭州悦容（西子） | U43: HZ Ruerong | V43: 2898.3322 | W43: -0.27755218 | X43: =X44+X45 -> 3400 | Y43: =X43/V43-1 -> 0.17308845 | Z43: 2616.931 | AA43: =Z43/V43-1 -> -0.097090738 | AB43: =Z43/X43 -> 0.76968558 | AC43: =D43+M43+V43 -> 8381.1313 | AD43: -0.17721022 | AE43: =F43+O43+X43 -> 8900 | AF43: =AE43/AC43-1 -> 0.061909152 | AG43: =H43+Q43+Z43 -> 6612.5285 | AH43: =AG43/AC43-1 -> -0.21102197 | AI43: =AG43/AE43 -> 0.74298073
B44: Wu huiling | D44: 727.976 | E44: 0.56073005 | F44: =F8 -> 300 | G44: =F44/D44-1 -> -0.5878985 | H44: 441.75903 | K44: Wu huiling | M44: 473.84215 | N44: -0.5288753 | O44: =O8 -> 300 | P44: =O44/M44-1 -> -0.36687777 | Q44: 320.944 | T44: Wu huiling | V44: 886.88188 | W44: -0.043368181 | X44: =X8 -> 300 | Y44: =X44/V44-1 -> -0.66173624 | Z44: 518.99899 | AC44: =D44+M44+V44 -> 2088.7 | AD44: -0.12945042 | AE44: =F44+O44+X44 -> 900 | AF44: =AE44/AC44-1 -> -0.56910998 | AG44: =H44+Q44+Z44 -> 1281.702
B45: 杭州悦容（西子） excl. Wu huiling | D45: 2737.8685 | E45: 0.60716969 | F45: 2800 | G45: =F45/D45-1 -> 0.022693376 | H45: =H43-H44 -> 2134.3092 | I45: =H45/D45-1 -> -0.22044862 | J45: =H45/F45 -> 0.76225328 | K45: 杭州悦容（西子） excl. Wu huiling | M45: 1543.1124 | N45: -0.48540262 | O45: 2100 | P45: =O45/M45-1 -> 0.36088594 | Q45: =Q43-Q44 -> 1098.5853 | R45: =Q45/M45-1 -> -0.28807178 | S45: =Q45/O45 -> 0.52313585 | T45: 杭州悦容（西子） excl. Wu huiling | V45: 2011.4503 | W45: -0.34793399 | X45: 3100 | Y45: =X45/V45-1 -> 0.54117653 | Z45: =Z43-Z44 -> 2097.932 | AB45: =Z45/X45 -> 0.67675225 | AC45: =D45+M45+V45 -> 6292.4312 | AD45: -0.19192582 | AE45: =F45+O45+X45 -> 8000 | AF45: =AE45/AC45-1 -> 0.27136868 | AG45: =H45+Q45+Z45 -> 5330.8264 | AH45: =AG45/AC45-1 -> -0.15281928 | AI45: =AG45/AE45 -> 0.6663533
...

Sheet 2025第二季度指标
B1: 消耗 | F1: 门店按自然月下指标，按自然月考核 | Q1: 门店按自然月下指标，按自然月考核 | AB1: 门店按自然月下指标，按自然月考核 | AL1: 门店按自然月下指标，按自然月考核
B2: YesSkin | D2: 2024年4月实际 | F2: 2025年4月指标 | H2: 2025年4月实际（自然月） | K2: YesSkin | M2: 2024年5月实际 | O2: 2025年5月指标-0326 | Q2: 2025年5月指标-0428 | S2: 2025年5月实际（自然月） | V2: YesSkin | X2: 2024年6月实际 | Z2: 2025年6月指标-0326 | AB2: 2025年6月指标-0520 | AD2: 2025年6月实际（自然月） | AH2: 2024年二季度 | AJ2: 2025年二季度指标-0326 | AL2: 2025年二季度指标-调整 | AN2: 2025年二季度实际
D3: 4月消耗 | E3: 增幅 | F3: 4月消耗 | G3: 增幅 | H3: 4月消耗 | I3: Evl% | J3: 指标达成率 | M3: 5月消耗 | N3: 增幅 | O3: 5月消耗 | P3: 增幅 | Q3: 5月消耗 | R3: 增幅 | S3: 5月消耗 | T3: Evl% | U3: 指标达成率 | X3: 6月消耗 | Y3: 增幅 | Z3: 6月消耗 | AA3: 增幅 | AB3: 6月消耗 | AC3: 增幅 | AD3: 6月消耗 | AE3: Evl% | AF3: 指标达成率 | AH3: 二季度消耗 | AI3: 增幅 | AJ3: 二季度消耗 | AK3: 增幅 | AL3: 二季度消耗 | AM3: 增幅 | AN3: 二季度消耗 | AO3: 增幅 | AP3: 指标达成率
B4: 全国合计 Total | D4: =D5+D12 -> 9887.5848 | E4: ='[1]consumption-2022-2025 retrend'!$G$246 -> -0.12318058 | F4: =F5+F12 -> 10826 | G4: =F4/D4-1 -> 0.094908438 | H4: =H5+H12 -> 8249.1125 | I4: =H4/D4-1 -> -0.16571006 | J4: =H4/F4 -> 0.76197233 | K4: National Total | M4: =M5+M12 -> 9759.0735 | N4: ='[1]consumption-2022-2025 retrend'!$H$246 -> -0.075817813 | O4: =O5+O12 -> 10916.66 | P4: =O4/M4-1 -> 0.11861643 | Q4: =Q5+Q12 -> 8750 | R4: =Q4/M4-1 -> -0.1033985 | S4: =S5+S12 -> 8089.6956 | T4: =S4/M4-1 -> -0.17105906 | U4: =S4/Q4 -> 0.92453664 | V4: National Total | X4: =X5+X12 -> 8155.2035 | Y4: ='[1]consumption-2022-2025 retrend'!$I$246 -> -0.1427834 | Z4: 11090 | AA4: =Z4/X4-1 -> 0.35986797 | AB4: =AB5+AB12 -> 8750 | AC4: =AB4/X4-1 -> 0.072934602 | AF4: =AD4/AB4 -> 0 | AH4: =AH5+AH12 -> 27801.862 | AI4: =AH4/'[2]consumption-2022-2025 retrend'!$S$125-1 -> -0.113176 | AJ4: =AJ5+AJ12 -> 32832.66 | AK4: =AJ4/AH4-1 -> 0.18095185 | AL4: =AL5+AL12 -> 28326 | AM4: =AL4/AH4-1 -> 0.01885263 | AP4: =AN4/AJ4 -> 0
B5: 杭州合计 | D5: =D6+D7+D10+D11 -> 7888.4493 | E5: ='[1]consumption-2022-2025 retrend'!$G$222 -> -0.12050377 | F5: =F6+F7+F10+F11 -> 8080 | G5: =F5/D5-1 -> 0.024282425 | H5: =H6+H7+H10+H11 -> 6813.3541 | I5: =H5/D5-1 -> -0.13628727 | J5: =H5/F5 -> 0.84323689 | K5: HZ Total | M5: =M6+M7+M10+M11 -> 7616.8034 | N5: ='[1]consumption-2022-2025 retrend'!$H$222 -> -0.12856326 | O5: =O6+O7+O10+O11 -> 7646.66 | P5: =O5/M5-1 -> 0.003919833 | Q5: =Q6+Q7+Q10+Q11 -> 6950 | R5: =Q5/M5-1 -> -0.087543737 | S5: =S6+S7+S10+S11 -> 6052.6481 | T5: =S5/M5-1 -> -0.20535587 | U5: =S5/Q5 -> 0.87088462 | V5: HZ Total | X5: =X6+X7+X10+X11 -> 6229.0379 | Y5: ='[1]consumption-2022-2025 retrend'!$I$222 -> -0.17324673 | Z5: 7840 | AA5: =Z5/X5-1 -> 0.25862133 | AB5: =AB6+AB7+AB10+AB11 -> 6800 | AC5: =AB5/X5-1 -> 0.091661355 | AF5: =AD5/AB5 -> 0 | AH5: =AH6+AH7+AH10+AH11 -> 21734.291 | AI5: =AH5/'[2]consumption-2022-2025 retrend'!$S$101-1 -> -0.13903589 | AJ5: =AJ6+AJ7+AJ10+AJ11 -> 23566.66 | AK5: =AJ5/AH5-1 -> 0.084307759 | AL5: =AL6+AL7+AL10+AL11 -> 21830 | AM5: =AL5/AH5-1 -> 0.0044036082 | AP5: =AN5/AJ5 -> 0
B6: 杭州时尚 | C6: HZ Fashion | D6: ='[1]consumption-2022-2025 retrend'!$G$224 -> 3539.223 | E6: ='[1]consumption-2022-2025 retrend'!$G$225 -> -0.084430672 | F6: 3900 | G6: =F6/D6-1 -> 0.10193678 | H6: 3544.7109 | I6: =H6/D6-1 -> 0.0015505918 | J6: =H6/F6 -> 0.90890023 | K6: 杭州时尚 | L6: HZ Fashion | M6: ='[1]consumption-2022-2025 retrend'!$H$224 -> 2817.5962 | N6: ='[1]consumption-2022-2025 retrend'!$H$225 -> -0.087294399 | O6: 3316.1714 | P6: =O6/M6-1 -> 0.17695054 | Q6: 3300 | R6: =Q6/M6-1 -> 0.17121111 | S6: 2963.9386 | T6: =S6/M6-1 -> 0.051938734 | U6: =S6/Q6 -> 0.89816321 | V6: 杭州时尚 | W6: HZ Fashion | X6: ='[1]consumption-2022-2025 retrend'!$I$224 -> 2850.6217 | Y6: ='[1]consumption-2022-2025 retrend'!$I$225 -> -0.048213257 | Z6: 3500 | AA6: =Z6/X6-1 -> 0.22780232 | AB6: 3350 | AC6: =AB6/X6-1 -> 0.17518223 | AF6: =AD6/AB6 -> 0 | AH6: =D6+M6+X6 -> 9207.441 | AI6: =AH6/'[2]consumption-2022-2025 retrend'!$S$104-1 -> -0.074415154 | AJ6: =F6+O6+Z6 -> 10716.171 | AK6: =AJ6/AH6-1 -> 0.16385991 | AL6: =F6+Q6+AB6 -> 10550 | AM6: =AL6/AH6-1 -> 0.1458124 | AP6: =AN6/AJ6 -> 0
B7: 杭州悦容（西子） | C7: HZ Ruerong | D7: ='[1]consumption-2022-2025 retrend'!$G$227 -> 2965.9416 | E7: ='[1]consumption-2022-2025 retrend'!$G$228 -> -0.090691738 | F7: 2700 | G7: =F7/D7-1 -> -0.089665144 | H7: 2363.7401 | I7: =H7/D7-1 -> -0.20303888 | J7: =H7/F7 -> 0.87545931 | K7: 杭州悦容（西子） | L7: HZ Ruerong | M7: ='[1]consumption-2022-2025 retrend'!$H$227 -> 3519.0258 | N7: ='[1]consumption-2022-2025 retrend'!$H$228 -> 0.25687086 | O7: 2800 | P7: =O7/M7-1 -> -0.20432524 | Q7: 2500 | R7: =Q7/M7-1 -> -0.28957611 | S7: 2075.1931 | T7: =S7/M7-1 -> -0.41029329 | U7: =S7/Q7 -> 0.83007725 | V7: 杭州悦容（西子） | W7: HZ Ruerong | X7: ='[1]consumption-2022-2025 retrend'!$I$227 -> 2356.6241 | Y7: ='[1]consumption-2022-2025 retrend'!$I$228 -> -0.20356461 | Z7: 2800 | AA7: =Z7/X7-1 -> 0.18814026 | AB7: 2250 | AC7: =AB7/X7-1 -> -0.045244432 | AF7: =AD7/AB7 -> 0 | AH7: =D7+M7+X7 -> 8841.5915 | AI7: =AH7/'[2]consumption-2022-2025 retrend'!$S$107-1 -> -0.019839124 | AJ7: =F7+O7+Z7 -> 8300 | AK7: =AJ7/AH7-1 -> -0.06125498 | AL7: =F7+Q7+AB7 -> 7450 | AM7: =AL7/AH7-1 -> -0.15739152 | AP7: =AN7/AJ7 -> 0
B8: 吴慧玲 | D8: ='[1]consumption-2022-2025 retrend'!$G$250 -> 694.88075 | E8: ='[1]consumption-2022-2025 retrend'!$G$251 -> -0.072696583 | F8: 300 | H8: 485.95885 | K8: 吴慧玲 | M8: ='[1]consumption-2022-2025 retrend'!$H$250 -> 540.4236 | N8: ='[1]consumption-2022-2025 retrend'!$H$251 -> -0.39605801 | O8: 454.8994 | Q8: 454.8994 | S8: 432.36891 | T8: =S8/M8-1 -> -0.19994443 | V8: 吴慧玲 | X8: ='[1]consumption-2022-2025 retrend'!$I$250 -> 496.3504 | Y8: ='[1]consumption-2022-2025 retrend'!$I$251 -> -0.44342969 | Z8: 300 | AB8: 480 | AH8: =D8+M8+X8 -> 1731.6547 | AI8: =AH8/'[2]consumption-2022-2025 retrend'!$S$130-1 -> -0.31716685 | AJ8: =F8+O8+Z8 -> 1054.8994 | AL8: =F8+Q8+AB8 -> 1234.8994
B9: 杭州悦容（西子） 不含吴慧玲 | D9: =D7-D8 -> 2271.0608 | E9: ='[1]consumption-2022-2025 retrend'!$G$253 -> -0.096059031 | F9: =F7-F8 -> 2400 | G9: =F9/D9-1 -> 0.056774864 | H9: =H7-H8 -> 1877.7813 | I9: =H9/D9-1 -> -0.17316998 | J9: =H9/F9 -> 0.78240887 | K9: 杭州悦容（西子） 不含吴慧玲 | M9: =M7-M8 -> 2978.6022 | N9: ='[1]consumption-2022-2025 retrend'!$H$253 -> 0.56356755 | O9: =O7-O8 -> 2345.1006 | P9: =O9/M9-1 -> -0.21268419 | Q9: =Q7-Q8 -> 2045.1006 | R9: =Q9/M9-1 -> -0.31340258 | S9: =S7-S8 -> 1642.8242 | T9: =S9/M9-1 -> -0.448458 | U9: =S9/Q9 -> 0.80329751 | V9: 杭州悦容（西子） 不含吴慧玲 | X9: =X7-X8 -> 1860.2737 | Y9: ='[1]consumption-2022-2025 retrend'!$I$253 -> -0.10008359 | Z9: 2500 | AA9: =Z9/X9-1 -> 0.34388825 | AB9: =AB7-AB8 -> 1770 | AC9: =AB9/X9-1 -> -0.048527117 | AF9: =AD9/AB9 -> 0 | AH9: =D9+M9+X9 -> 7109.9368 | AI9: =AH9/'[2]consumption-2022-2025 retrend'!$S$132-1 -> 0.096439854 | AJ9: =F9+O9+Z9 -> 7245.1006 | AL9: =F9+Q9+AB9 -> 6215.1006 | AM9: =AL9/AH9-1 -> -0.12585712 | AP9: =AN9/AJ9 -> 0
B10: 杭州素颜丰潭（城西） | C10: HZ Suyan Fengtan(West) | D10: ='[1]consumption-2022-2025 retrend'!$G$230 -> 661.17768 | E10: ='[1]consumption-2022-2025 retrend'!$G$231 -> -0.38810991 | F10: 680 | G10: =F10/D10-1 -> 0.02846787 | H10: 386.90371 | I10: =H10/D10-1 -> -0.41482642 | J10: =H10/F10 -> 0.56897604 | K10: 杭州素颜丰潭（城西） | L10: HZ Suyan Fengtan(West) | M10: ='[1]consumption-2022-2025 retrend'!$H$230 -> 503.78065 | N10: ='[1]consumption-2022-2025 retrend'!$H$231 -> -0.7568748 | O10: 670 | P10: =O10/M10-1 -> 0.3299439 | Q10: 500 | R10: =Q10/M10-1 -> -0.0075045558 | S10: 448.5202 | T10: =S10/M10-1 -> -0.10969149 | U10: =S10/Q10 -> 0.8970404 | V10: 杭州素颜丰潭（城西） | W10: HZ Suyan Fengtan(West) | X10: ='[1]consumption-2022-2025 retrend'!$I$230 -> 537.05476 | Y10: ='[1]consumption-2022-2025 retrend'!$I$231 -> -0.39069151 | Z10: 650 | AA10: =Z10/X10-1 -> 0.21030489 | AB10: 510 | AC10: =AB10/X10-1 -> -0.050376166 | AF10: =AD10/AB10 -> 0 | AH10: =D10+M10+X10 -> 1702.0131 | AI10: =AH10/'[2]consumption-2022-2025 retrend'!$S$110-1 -> -0.57809038 | AJ10: =F10+O10+Z10 -> 2000 | AK10: =AJ10/AH10-1 -> 0.17507909 | AL10: =F10+Q10+AB10 -> 1690 | AM10: =AL10/AH10-1 -> -0.0070581655 | AP10: =AN10/AJ10 -> 0
B11: 杭州新芽（万通） | C11: HZ Xinya | D11: ='[1]consumption-2022-2025 retrend'!$G$233 -> 722.10707 | E11: ='[1]consumption-2022-2025 retrend'!$G$234 -> -0.051578594 | F11: 800 | G11: =F11/D11-1 -> 0.10786895 | H11: 517.99938 | I11: =H11/D11-1 -> -0.28265571 | J11: =H11/F11 -> 0.64749923 | K11: 杭州新芽（万通） | L11: HZ Xinya | M11: ='[1]consumption-2022-2025 retrend'!$H$233 -> 776.40076 | N11: ='[1]consumption-2022-2025 retrend'!$H$234 -> -0.0065203627 | O11: ='[1]0225 SRI03'!$H$94 -> 860.48865 | P11: =O11/M11-1 -> 0.10830475 | Q11: 650 | R11: =Q11/M11-1 -> -0.1628035 | S11: 564.99621 | T11: =S11/M11-1 -> -0.27228792 | U11: =S11/Q11 -> 0.86922494 | V11: 杭州新芽（万通） | W11: HZ Xinya | X11: ='[1]consumption-2022-2025 retrend'!$I$233 -> 484.73732 | Y11: ='[1]consumption-2022-2025 retrend'!$I$234 -> -0.30646228 | Z11: 890 | AA11: =Z11/X11-1 -> 0.83604596 | AB11: 690 | AC11: =AB11/X11-1 -> 0.42345137 | AF11: =AD11/AB11 -> 0 | AH11: =D11+M11+X11 -> 1983.2451 | AI11: =AH11/'[2]consumption-2022-2025 retrend'!$S$113-1 -> -0.11533699 | AJ11: =F11+O11+Z11 -> 2550.4887 | AK11: =AJ11/AH11-1 -> 0.28601784 | AL11: =F11+Q11+AB11 -> 2140 | AM11: =AL11/AH11-1 -> 0.079039573 | AP11: =AN11/AJ11 -> 0
B12: 杭外合计 | D12: =D13+D14 -> 1999.1355 | E12: ='[1]consumption-2022-2025 retrend'!$G$237 -> -0.13358599 | F12: =F13+F14 -> 2746 | G12: =F12/D12-1 -> 0.37359377 | H12: =H13+H14 -> 1435.7584 | I12: =H12/D12-1 -> -0.28181035 | J12: =H12/F12 -> 0.52285447 | K12: outsize HZ Total | M12: =M13+M14 -> 2142.2701 | N12: ='[1]consumption-2022-2025 retrend'!$H$237 -> 0.17760614 | O12: =O13+O14 -> 3270 | P12: =O12/M12-1 -> 0.52641817 | Q12: =Q13+Q14 -> 1800 | R12: =Q12/M12-1 -> -0.15976981 | S12: =S13+S14 -> 2037.0474 | T12: =S12/M12-1 -> -0.049117369 | U12: =S12/Q12 -> 1.131693 | V12: outsize HZ Total | X12: =X13+X14 -> 1926.1655 | Y12: ='[1]consumption-2022-2025 retrend'!$I$237 -> -0.026819671 | Z12: 3250 | AA12: =Z12/X12-1 -> 0.68729008 | AB12: =AB13+AB14 -> 1950 | AC12: =AB12/X12-1 -> 0.012374045 | AF12: =AD12/AB12 -> 0 | AH12: =AH13+AH14 -> 6067.5711 | AI12: =AH12/'[2]consumption-2022-2025 retrend'!$S$116-1 -> -0.0062593593 | AJ12: =AJ13+AJ14 -> 9266 | AK12: =AJ12/AH12-1 -> 0.52713497 | AL12: =AL13+AL14 -> 6496 | AM12: =AL12/AH12-1 -> 0.070609625 | AP12: =AN12/AJ12 -> 0
B13: 上海诊所 | C13: SH Clinic | D13: ='[1]consumption-2022-2025 retrend'!$G$239 -> 1253.0205 | E13: ='[1]consumption-2022-2025 retrend'!$G$240 -> -0.19164444 | F13: 2000 | G13: =F13/D13-1 -> 0.59614308 | H13: 1032.458 | I13: =H13/D13-1 -> -0.17602467 | J13: =H13/F13 -> 0.51622899 | K13: 上海诊所 | L13: SH Clinic | M13: ='[1]consumption-2022-2025 retrend'!$H$239 -> 1460.4868 | N13: ='[1]consumption-2022-2025 retrend'!$H$240 -> 0.23469141 | O13: 2500 | P13: =O13/M13-1 -> 0.71175808 | Q13: 1200 | R13: =Q13/M13-1 -> -0.17835612 | S13: 1425.8618 | T13: =S13/M13-1 -> -0.023707843 | U13: =S13/Q13 -> 1.1882181 | V13: 上海诊所 | W13: SH Clinic | X13: ='[1]consumption-2022-2025 retrend'!$I$239 -> 1318.7824 | Y13: ='[1]consumption-2022-2025 retrend'!$I$240 -> 0.010836166 | Z13: 2500 | AA13: =Z13/X13-1 -> 0.89568808 | AB13: 1350 | AC13: =AB13/X13-1 -> 0.023671563 | AF13: =AD13/AB13 -> 0 | AH13: =D13+M13+X13 -> 4032.2896 | AI13: =AH13/'[2]consumption-2022-2025 retrend'!$S$119-1 -> -0.0013169113 | AJ13: =F13+O13+Z13 -> 7000 | AK13: =AJ13/AH13-1 -> 0.73598642 | AL13: =F13+Q13+AB13 -> 4550 | AM13: =AL13/AH13-1 -> 0.12839117 | AP13: =AN13/AJ13 -> 0
B14: 苏州诊所 | C14: Suzhuo Clinic | D14: ='[1]consumption-2022-2025 retrend'!$G$242 -> 746.11495 | E14: ='[1]consumption-2022-2025 retrend'!$G$243 -> -0.014745665 | F14: 746 | G14: =F14/D14-1 -> -0.00015406473 | H14: 403.3004 | I14: =H14/D14-1 -> -0.45946613 | J14: =H14/F14 -> 0.54061716 | K14: 苏州诊所 | L14: Suzhuo Clinic | M14: ='[1]consumption-2022-2025 retrend'!$H$242 -> 681.78334 | N14: ='[1]consumption-2022-2025 retrend'!$H$243 -> 0.071484774 | O14: 770 | P14: =O14/M14-1 -> 0.12939105 | Q14: 600 | R14: =Q14/M14-1 -> -0.11995503 | S14: 611.18566 | T14: =S14/M14-1 -> -0.10354856 | U14: =S14/Q14 -> 1.0186428 | V14: 苏州诊所 | W14: Suzhuo Clinic | X14: ='[1]consumption-2022-2025 retrend'!$I$242 -> 607.38318 | Y14: ='[1]consumption-2022-2025 retrend'!$I$243 -> -0.099643951 | Z14: 750 | AA14: =Z14/X14-1 -> 0.23480535 | AB14: 600 | AC14: =AB14/X14-1 -> -0.01215572 | AF14: =AD14/AB14 -> 0 | AH14: =D14+M14+X14 -> 2035.2815 | AI14: =AH14/'[2]consumption-2022-2025 retrend'!$S$122-1 -> -0.015908247 | AJ14: =F14+O14+Z14 -> 2266 | AK14: =AJ14/AH14-1 -> 0.11335952 | AL14: =F14+Q14+AB14 -> 1946 | AM14: =AL14/AH14-1 -> -0.043866891 | AP14: =AN14/AJ14 -> 0
B15: 杭州不含吴慧玲 | D15: =D5-D8 -> 7193.5686 | E15: ='[1]consumption-2022-2025 retrend'!$G$255 -> -0.12486203 | F15: =F5-F8 -> 7780 | G15: =F15/D15-1 -> 0.081521629 | H15: =H5-H8 -> 6327.3953 | I15: =H15/D15-1 -> -0.12040941 | J15: =H15/F15 -> 0.81328988 | K15: 杭州不含吴慧玲 | M15: =M5-M8 -> 7076.3798 | N15: ='[1]consumption-2022-2025 retrend'!$H$255 -> -0.098054572 | O15: =O5-O8 -> 7191.7606 | P15: =O15/M15-1 -> 0.01630506 | Q15: =Q5-Q8 -> 6495.1006 | R15: =Q15/M15-1 -> -0.082143589 | S15: =S5-S8 -> 5620.2792 | T15: =S15/M15-1 -> -0.20576914 | U15: =S15/Q15 -> 0.86531057 | V15: 杭州不含吴慧玲 | X15: =X5-X8 -> 5732.6875 | Y15: ='[1]consumption-2022-2025 retrend'!$I$255 -> -0.13697299 | Z15: 7540 | AA15: =Z15/X15-1 -> 0.31526443 | AB15: =AB5-AB8 -> 6320 | AC15: =AB15/X15-1 -> 0.10244976 | AF15: =AD15/AB15 -> 0 | AH15: =AH5-AH8 -> 20002.636 | AI15: =AH15/'[2]consumption-2022-2025 retrend'!$S$134-1 -> -0.1191427 | AJ15: =F15+O15+Z15 -> 22511.761 | AK15: =AJ15/AH15-1 -> 0.1254397 | AL15: =F15+Q15+AB15 -> 20595.101 | AM15: =AL15/AH15-1 -> 0.029619329 | AP15: =AN15/AJ15 -> 0
B16: 全国不含吴慧玲 | D16: =D4-D8 -> 9192.704 | E16: ='[1]consumption-2022-2025 retrend'!$G$257 -> -0.12677415 | F16: =F4-F8 -> 10526 | G16: =F16/D16-1 -> 0.1450385 | H16: =H4-H8 -> 7763.1536 | I16: =H16/D16-1 -> -0.15550924 | J16: =H16/F16 -> 0.73752172 | K16: 全国不含吴慧玲 | M16: =M4-M8 -> 9218.6499 | N16: ='[1]consumption-2022-2025 retrend'!$H$257 -> -0.046168174 | O16: =O4-O8 -> 10461.761 | P16: =O16/M16-1 -> 0.13484737 | Q16: =Q4-Q8 -> 8295.1006 | R16: =Q16/M16-1 -> -0.10018271 | S16: =S4-S8 -> 7657.3267 | T16: =S16/M16-1 -> -0.16936572 | U16: =S16/Q16 -> 0.92311438 | V16: 全国不含吴慧玲 | X16: =X4-X8 -> 7658.8531 | Y16: ='[1]consumption-2022-2025 retrend'!$I$257 -> -0.11168579 | Z16: 10790 | AA16: =Z16/X16-1 -> 0.40882713 | AB16: =AB4-AB8 -> 8270 | AC16: =AB16/X16-1 -> 0.079796141 | AF16: =AD16/AB16 -> 0 | AH16: =AH4-AH8 -> 26070.207 | AI16: =AH16/'[2]consumption-2022-2025 retrend'!$S$136-1 -> -0.095222263 | AJ16: =F16+O16+Z16 -> 31777.761 | AK16: =AJ16/AH16-1 -> 0.21893012 | AL16: =F16+Q16+AB16 -> 27091.101 | AM16: =AL16/AH16-1 -> 0.039159396 | AP16: =AN16/AJ16 -> 0
B21: 开单 | F21: 门店按自然月下指标，按自然月考核 | Q21: 门店按自然月下指标，按自然月考核 | AB21: 门店按自然月下指标，按自然月考核 | AL21: 门店按自然月下指标，按自然月考核
B22: YesSkin | D22: 2024年4月实际 | F22: 2025年4月指标 | H22: 2025年4月实际（自然月） | K22: YesSkin | M22: 2024年5月实际 | O22: 2025年5月指标 | Q22: 2025年5月指标-0428 | S22: 2025年5月实际（自然月） | V22: YesSkin | X22: 2024年6月实际 | Z22: 2025年6月指标-0326 | AB22: 2025年6月指标-0520 | AD22: 2025年6月实际（自然月） | AH22: 2024年二季度 | AJ22: 2025年二季度指标-0326 | AL22: 2025年二季度指标-调整 | AN22: 2025年二季度实际
D23: 4月开单 | E23: 增幅 | F23: 4月开单 | G23: 增幅 | H23: 4月开单 | I23: Evl% | J23: 指标达成率 | M23: 5月开单 | N23: 增幅 | O23: 5月开单 | P23: 增幅 | Q23: 5月开单 | R23: 增幅 | S23: 5月开单 | T23: Evl% | U23: 指标达成率 | X23: 6月开单 | Y23: 增幅 | Z23: 6月开单 | AA23: 增幅 | AB23: 6月开单 | AC23: 增幅 | AD23: 6月开单 | AE23: Evl% | AF23: 指标达成率 | AH23: 二季度开单 | AI23: 增幅 | AJ23: 二季度开单 | AK23: 增幅 | AL23: 二季度开单 | AM23: 增幅 | AN23: 二季度开单 | AO23: 增幅
B24: National Total | D24: =D25+D32 -> 9535.8473 | E24: ='[1]billing 2022-2025 retrend'!$G$246 -> -0.10840249 | F24: =F25+F32 -> 9520 | G24: =F24/D24-1 -> -0.001661866 | H24: =H25+H32 -> 8640.1224 | I24: =H24/D24-1 -> -0.093932388 | J24: =H24/F24 -> 0.90757588 | K24: National Total | M24: =M25+M32 -> 9057.9313 | N24: ='[1]billing 2022-2025 retrend'!$H$246 -> -0.14860763 | O24: =O25+O32 -> 10668.206 | P24: =O24/M24-1 -> 0.17777506 | Q24: =Q25+Q32 -> 8300 | R24: =Q24/O24-1 -> -0.22198725 | S24: =S25+S32 -> 8002.3672 | T24: =S24/M24-1 -> -0.11653479 | U24: =S24/Q24 -> 0.96414062 | V24: National Total | X24: =X25+X32 -> 9458.2973 | Y24: ='[1]billing 2022-2025 retrend'!$I$246 -> -0.16247701 | Z24: 11110 | AA24: =Z24/X24-1 -> 0.17463003 | AB24: =AB25+AB32 -> 8300 | AC24: =AB24/X24-1 -> -0.12246361 | AF24: =AD24/AB24 -> 0 | AH24: =AH25+AH32 -> 28052.076 | AI24: =AH24/'[2]billing 2022-2025 retrend'!$S$125-1 -> -0.14022896 | AJ24: =AJ25+AJ32 -> 31298.206 | AK24: =AJ24/AH24-1 -> 0.11571799 | AL24: =AL25+AL32 -> 26120 | AM24: =AL24/AH24-1 -> -0.068874612 | AP24: 指标达成率
B25: HZ Total | D25: =D26+D27+D30+D31 -> 7893.3375 | E25: ='[1]billing 2022-2025 retrend'!$G$222 -> -0.082502004 | F25: =F26+F27+F30+F31 -> 7020 | G25: =F25/D25-1 -> -0.11064236 | H25: =H26+H27+H30+H31 -> 6926.2498 | I25: =H25/D25-1 -> -0.12251949 | J25: =H25/F25 -> 0.98664527 | K25: HZ Total | M25: =M26+M27+M30+M31 -> 6951.1752 | N25: ='[1]billing 2022-2025 retrend'!$H$222 -> -0.23488214 | O25: =O26+O27+O30+O31 -> 7714.2056 | P25: =O25/M25-1 -> 0.10976998 | Q25: =Q26+Q27+Q30+Q31 -> 6800 | R25: =Q25/O25-1 -> -0.11850936 | S25: =S26+S27+S30+S31 -> 6079.1612 | T25: =S25/M25-1 -> -0.12544843 | U25: =S25/Q25 -> 0.89399429 | V25: HZ Total | X25: =X26+X27+X30+X31 -> 7711.9234 | Y25: ='[1]billing 2022-2025 retrend'!$I$222 -> -0.15510112 | Z25: 7810 | AA25: =Z25/X25-1 -> 0.012717529 | AB25: =AB26+AB27+AB30+AB31 -> 6350 | AC25: =AB25/X25-1 -> -0.1765997 | AF25: =AD25/AB25 -> 0 | AH25: =AH26+AH27+AH30+AH31 -> 22556.436 | AI25: =AH25/'[2]billing 2022-2025 retrend'!$S$101-1 -> -0.15883923 | AJ25: =AJ26+AJ27+AJ30+AJ31 -> 22544.206 | AK25: =AJ25/AH25-1 -> -0.00054221616 | AL25: =AL26+AL27+AL30+AL31 -> 20170 | AM25: =AL25/AH25-1 -> -0.10579845 | AP25: =AN25/AJ25 -> 0
B26: 杭州时尚 | C26: HZ Fashion | D26: ='[1]billing 2022-2025 retrend'!$G$224 -> 3211.7033 | E26: ='[1]billing 2022-2025 retrend'!$G$225 -> -0.015688796 | F26: 3500 | G26: =F26/D26-1 -> 0.089764415 | H26: 3410.7517 | I26: =H26/D26-1 -> 0.061975952 | J26: =H26/F26 -> 0.97450049 | K26: 杭州时尚 | L26: HZ Fashion | M26: ='[1]billing 2022-2025 retrend'!$H$224 -> 2370.415 | N26: ='[1]billing 2022-2025 retrend'!$H$225 -> -0.25613069 | O26: 3400 | P26: =O26/M26-1 -> 0.43434801 | Q26: 3300 | R26: =Q26/O26-1 -> -0.029411765 | S26: 2771.9905 | T26: =S26/M26-1 -> 0.16941147 | U26: =S26/Q26 -> 0.83999711 | V26: 杭州时尚 | W26: HZ Fashion | X26: ='[1]billing 2022-2025 retrend'!$I$224 -> 2877.3127 | Y26: ='[1]billing 2022-2025 retrend'!$I$225 -> -0.22200402 | Z26: 3500 | AA26: =Z26/X26-1 -> 0.2164128 | AB26: 3100 | AC26: =AB26/X26-1 -> 0.077394191 | AF26: =AD26/AB26 -> 0 | AH26: =D26+M26+X26 -> 8459.431 | AI26: =AH26/'[2]billing 2022-2025 retrend'!$S$104-1 -> -0.16638277 | AJ26: =F26+O26+Z26 -> 10400 | AK26: =AJ26/AH26-1 -> 0.2293971 | AL26: =F26+Q26+AB26 -> 9900 | AM26: =AL26/AH26-1 -> 0.17029147 | AP26: =AN26/AJ26 -> 0
B27: 杭州悦容（西子） | C27: HZ Ruerong | D27: ='[1]billing 2022-2025 retrend'!$G$227 -> 2974.6705 | E27: ='[1]billing 2022-2025 retrend'!$G$228 -> -0.071485432 | F27: 2300 | G27: =F27/D27-1 -> -0.22680511 | H27: 2245.2586 | I27: =H27/D27-1 -> -0.24520762 | J27: =H27/F27 -> 0.9761994 | K27: 杭州悦容（西子） | L27: HZ Ruerong | M27: ='[1]billing 2022-2025 retrend'!$H$227 -> 3512.6178 | N27: ='[1]billing 2022-2025 retrend'!$H$228 -> 0.14147909 | O27: 2939.0156 | P27: =O27/M27-1 -> -0.16329763 | Q27: 2500 | R27: =Q27/O27-1 -> -0.14937506 | S27: 2067.3816 | T27: =S27/M27-1 -> -0.41144134 | U27: =S27/Q27 -> 0.82695266 | V27: 杭州悦容（西子） | W27: HZ Ruerong | X27: ='[1]billing 2022-2025 retrend'!$I$227 -> 3318.0577 | Y27: ='[1]billing 2022-2025 retrend'!$I$228 -> -0.10615619 | Z27: 2800 | AA27: =Z27/X27-1 -> -0.15613281 | AB27: 2100 | AC27: =AB27/X27-1 -> -0.36709961 | AF27: =AD27/AB27 -> 0 | AH27: =D27+M27+X27 -> 9805.3459 | AI27: =AH27/'[2]billing 2022-2025 retrend'!$S$107-1 -> -0.018784543 | AJ27: =F27+O27+Z27 -> 8039.0156 | AK27: =AJ27/AH27-1 -> -0.18013952 | AL27: =F27+Q27+AB27 -> 6900 | AM27: =AL27/AH27-1 -> -0.29630224 | AP27: =AN27/AJ27 -> 0
B28: Wu huiling | D28: ='[1]billing 2022-2025 retrend'!$G$250 -> 701.37015 | E28: ='[1]billing 2022-2025 retrend'!$G$251 -> -0.11983641 | F28: 300 | H28: 462.4129 | K28: Wu huiling | M28: ='[1]billing 2022-2025 retrend'!$H$250 -> 557.928 | N28: ='[1]billing 2022-2025 retrend'!$H$251 -> -0.44389281 | O28: ='[1]0225 SRI03'!$H$201 -> 454.8994 | Q28: ='[1]0225 SRI03'!$H$201 -> 454.8994 | S28: 463.5532 | T28: =S28/M28-1 -> -0.16915229 | V28: Wu huiling | X28: ='[1]billing 2022-2025 retrend'!$I$250 -> 538.73723 | Y28: ='[1]billing 2022-2025 retrend'!$I$251 -> -0.41327193 | Z28: 300 | AB28: =AB8 -> 480 | AH28: =D28+M28+X28 -> 1798.0354 | AI28: =AH28/'[2]billing 2022-2025 retrend'!$S$130-1 -> -0.33855478 | AJ28: =F28+O28+Z28 -> 1054.8994 | AL28: =F28+Q28+AB28 -> 1234.8994 | AP28: =AN28/AJ28 -> 0
B29: 杭州悦容（西子） excl. Wu huiling | D29: =D27-D28 -> 2273.3003 | E29: ='[1]billing 2022-2025 retrend'!$G$253 -> -0.055477146 | F29: =F27-F28 -> 2000 | G29: =F29/D29-1 -> -0.12022183 | H29: =H27-H28 -> 1782.8457 | I29: =H29/D29-1 -> -0.21574563 | J29: =H29/F29 -> 0.89142286 | K29: 杭州悦容（西子） excl. Wu huiling | M29: =M27-M28 -> 2954.6898 | N29: ='[1]billing 2022-2025 retrend'!$H$253 -> 0.42464932 | O29: =O27-O28 -> 2484.1162 | P29: =O29/M29-1 -> -0.15926327 | Q29: =Q27-Q28 -> 2045.1006 | R29: =Q29/O29-1 -> -0.17672911 | S29: =S27-S28 -> 1603.8284 | T29: =S29/M29-1 -> -0.45719228 | U29: =S29/Q29 -> 0.78422961 | V29: 杭州悦容（西子） excl. Wu huiling | X29: =X27-X28 -> 2779.3205 | Y29: ='[1]billing 2022-2025 retrend'!$I$253 -> -0.0052242149 | Z29: 2500 | AA29: =Z29/X29-1 -> -0.10049955 | AB29: =AB27-AB28 -> 1620 | AC29: =AB29/X29-1 -> -0.41712371 | AF29: =AD29/AB29 -> 0 | AH29: =D29+M29+X29 -> 8007.3106 | AI29: =AH29/'[2]billing 2022-2025 retrend'!$S$132-1 -> 0.100704 | AJ29: =F29+O29+Z29 -> 6984.1162 | AL29: =F29+Q29+AB29 -> 5665.1006 | AM29: =AL29/AH29-1 -> -0.29250895
B30: 杭州素颜丰潭（城西） | C30: HZ Suyan Fengtan(West) | D30: ='[1]billing 2022-2025 retrend'!$G$230 -> 894.25425 | E30: ='[1]billing 2022-2025 retrend'!$G$231 -> -0.249692 | F30: 550 | G30: =F30/D30-1 -> -0.38496239 | H30: 578.3779 | I30: =H30/D30-1 -> -0.35322879 | J30: =H30/F30 -> 1.0515962 | K30: 杭州素颜丰潭（城西） | L30: HZ Suyan Fengtan(West) | M30: ='[1]billing 2022-2025 retrend'!$H$230 -> 442.59879 | N30: ='[1]billing 2022-2025 retrend'!$H$231 -> -0.77449854 | O30: 514.70129 | P30: =O30/M30-1 -> 0.16290714 | Q30: 450 | R30: =Q30/O30-1 -> -0.12570649 | S30: 502.93147 | T30: =S30/M30-1 -> 0.13631461 | U30: =S30/Q30 -> 1.1176255 | V30: 杭州素颜丰潭（城西） | W30: HZ Suyan Fengtan(West) | X30: ='[1]billing 2022-2025 retrend'!$I$230 -> 861.0851 | Y30: ='[1]billing 2022-2025 retrend'!$I$231 -> -0.034371096 | Z30: 610 | AA30: =Z30/X30-1 -> -0.2915915 | AB30: 500 | AC30: =AB30/X30-1 -> -0.4193373 | AF30: =AD30/AB30 -> 0 | AH30: =D30+M30+X30 -> 2197.9381 | AI30: =AH30/'[2]billing 2022-2025 retrend'!$S$110-1 -> -0.4568051 | AJ30: =F30+O30+Z30 -> 1674.7013 | AK30: =AJ30/AH30-1 -> -0.23805804 | AL30: =F30+Q30+AB30 -> 1500 | AM30: =AL30/AH30-1 -> -0.31754221 | AP30: =AN30/AJ30 -> 0
B31: 杭州新芽（万通） | C31: HZ Xinya | D31: ='[1]billing 2022-2025 retrend'!$G$233 -> 812.70942 | E31: ='[1]billing 2022-2025 retrend'!$G$234 -> -0.13969889 | F31: 670 | G31: =F31/D31-1 -> -0.1755971 | H31: 691.86158 | I31: =H31/D31-1 -> -0.14869748 | J31: =H31/F31 -> 1.0326292 | K31: 杭州新芽（万通） | L31: HZ Xinya | M31: ='[1]billing 2022-2025 retrend'!$H$233 -> 625.54362 | N31: ='[1]billing 2022-2025 retrend'!$H$234 -> -0.2713698 | O31: 860.48865 | P31: =O31/M31-1 -> 0.37558537 | Q31: 550 | R31: =Q31/O31-1 -> -0.36082829 | S31: 736.85759 | T31: =S31/M31-1 -> 0.17794757 | U31: =S31/Q31 -> 1.3397411 | V31: 杭州新芽（万通） | W31: HZ Xinya | X31: ='[1]billing 2022-2025 retrend'!$I$233 -> 655.4679 | Y31: ='[1]billing 2022-2025 retrend'!$I$234 -> -0.20588511 | Z31: 900 | AA31: =Z31/X31-1 -> 0.37306495 | AB31: 650 | AC31: =AB31/X31-1 -> -0.0083419798 | AF31: =AD31/AB31 -> 0 | AH31: =D31+M31+X31 -> 2093.7209 | AI31: =AH31/'[2]billing 2022-2025 retrend'!$S$113-1 -> -0.20348654 | AJ31: =F31+O31+Z31 -> 2430.4887 | AK31: =AJ31/AH31-1 -> 0.16084651 | AL31: =F31+Q31+AB31 -> 1870 | AM31: =AL31/AH31-1 -> -0.10685328 | AP31: =AN31/AJ31 -> 0
B32: outsize HZ Total | D32: =D33+D34 -> 1642.5098 | E32: ='[1]billing 2022-2025 retrend'!$G$237 -> -0.21490887 | F32: =F33+F34 -> 2500 | G32: =F32/D32-1 -> 0.52206091 | H32: =H33+H34 -> 1713.8726 | I32: =H32/D32-1 -> 0.043447393 | J32: =H32/F32 -> 0.68554904 | K32: outsize HZ Total | M32: =M33+M34 -> 2106.7561 | N32: ='[1]billing 2022-2025 retrend'!$H$237 -> 0.35582249 | O32: =O33+O34 -> 2954 | P32: =O32/M32-1 -> 0.40215567 | Q32: =Q33+Q34 -> 1500 | R32: =Q32/O32-1 -> -0.49221395 | S32: =S33+S34 -> 1923.206 | T32: =S32/M32-1 -> -0.087124514 | U32: =S32/Q32 -> 1.2821373 | V32: outsize HZ Total | X32: =X33+X34 -> 1746.3739 | Y32: ='[1]billing 2022-2025 retrend'!$I$237 -> -0.19356583 | Z32: 3300 | AA32: =Z32/X32-1 -> 0.88962974 | AB32: =AB33+AB34 -> 1950 | AC32: =AB32/X32-1 -> 0.11659939 | AF32: =AD32/AB32 -> 0 | AH32: =AH33+AH34 -> 5495.6398 | AI32: =AH32/'[2]billing 2022-2025 retrend'!$S$116-1 -> -0.054356607 | AJ32: =AJ33+AJ34 -> 8754 | AK32: =AJ32/AH32-1 -> 0.59289916 | AL32: =AL33+AL34 -> 5950 | AM32: =AL32/AH32-1 -> 0.08267649 | AP32: =AN32/AJ32 -> 0
B33: 上海诊所 | C33: SH Clinic | D33: ='[1]billing 2022-2025 retrend'!$G$239 -> 962.5089 | E33: ='[1]billing 2022-2025 retrend'!$G$240 -> -0.24720286 | F33: 1900 | G33: =F33/D33-1 -> 0.97400772 | H33: 1178.1575 | I33: =H33/D33-1 -> 0.22404843 | J33: =H33/F33 -> 0.6200829 | K33: 上海诊所 | L33: SH Clinic | M33: ='[1]billing 2022-2025 retrend'!$H$239 -> 1374.423 | N33: ='[1]billing 2022-2025 retrend'!$H$240 -> 0.48015992 | O33: 2200 | P33: =O33/M33-1 -> 0.60067168 | Q33: 1100 | R33: =Q33/O33-1 -> -0.5 | S33: 1348.1608 | T33: =S33/M33-1 -> -0.019107793 | U33: =S33/Q33 -> 1.2256008 | V33: 上海诊所 | W33: SH Clinic | X33: ='[1]billing 2022-2025 retrend'!$I$239 -> 1093.6299 | Y33: ='[1]billing 2022-2025 retrend'!$I$240 -> -0.18283451 | Z33: 2500 | AA33: =Z33/X33-1 -> 1.2859652 | AB33: 1350 | AC33: =AB33/X33-1 -> 0.23442123 | AF33: =AD33/AB33 -> 0 | AH33: =D33+M33+X33 -> 3430.5619 | AI33: =AH33/'[2]billing 2022-2025 retrend'!$S$119-1 -> -0.032407623 | AJ33: =F33+O33+Z33 -> 6600 | AK33: =AJ33/AH33-1 -> 0.92388311 | AL33: =F33+Q33+AB33 -> 4350 | AM33: =AL33/AH33-1 -> 0.26801387 | AP33: =AN33/AJ33 -> 0
B34: 苏州诊所 | C34: Suzhuo Clinic | D34: ='[1]billing 2022-2025 retrend'!$G$242 -> 680.00093 | E34: ='[1]billing 2022-2025 retrend'!$G$243 -> -0.16415555 | F34: 600 | G34: =F34/D34-1 -> -0.11764827 | H34: 535.71509 | I34: =H34/D34-1 -> -0.21218477 | J34: =H34/F34 -> 0.89285848 | K34: 苏州诊所 | L34: Suzhuo Clinic | M34: ='[1]billing 2022-2025 retrend'!$H$242 -> 732.33307 | N34: ='[1]billing 2022-2025 retrend'!$H$243 -> 0.17118109 | O34: 754 | P34: =O34/M34-1 -> 0.029586169 | Q34: 400 | R34: =Q34/O34-1 -> -0.46949602 | S34: 575.04516 | T34: =S34/M34-1 -> -0.21477647 | U34: =S34/Q34 -> 1.4376129 | V34: 苏州诊所 | W34: Suzhuo Clinic | X34: ='[1]billing 2022-2025 retrend'!$I$242 -> 652.74394 | Y34: ='[1]billing 2022-2025 retrend'!$I$243 -> -0.21092734 | Z34: 800 | AA34: =Z34/X34-1 -> 0.22559545 | AB34: 600 | AC34: =AB34/X34-1 -> -0.080803416 | AF34: =AD34/AB34 -> 0 | AH34: =D34+M34+X34 -> 2065.0779 | AI34: =AH34/'[2]billing 2022-2025 retrend'!$S$122-1 -> -0.088697635 | AJ34: =F34+O34+Z34 -> 2154 | AK34: =AJ34/AH34-1 -> 0.043059905 | AL34: =F34+Q34+AB34 -> 1600 | AM34: =AL34/AH34-1 -> -0.22521084 | AP34: =AN34/AJ34 -> 0
B35: 杭州不含吴慧玲 | D35: =D25-D28 -> 7191.9673 | E35: ='[1]billing 2022-2025 retrend'!$G$255 -> -0.0786909 | F35: =F25-F28 -> 6720 | G35: =F35/D35-1 -> -0.06562423 | H35: =H25-H28 -> 6463.8369 | I35: =H35/D35-1 -> -0.10124218 | J35: =H35/F35 -> 0.96188049 | K35: 杭州不含吴慧玲 | M35: =M25-M28 -> 6393.2472 | N35: ='[1]billing 2022-2025 retrend'!$H$255 -> -0.20893567 | O35: =O25-O28 -> 7259.3062 | P35: =O35/M35-1 -> 0.13546465 | Q35: =Q25-Q28 -> 6345.1006 | R35: =Q35/O35-1 -> -0.12593567 | S35: =S25-S28 -> 5615.608 | T35: =S35/M35-1 -> -0.12163447 | U35: =S35/Q35 -> 0.88503056 | V35: 杭州不含吴慧玲 | X35: =X25-X28 -> 7173.1862 | Y35: ='[1]billing 2022-2025 retrend'!$I$255 -> -0.12622528 | Z35: 7510 | AA35: =Z35/X35-1 -> 0.046954566 | AB35: =AB25-AB28 -> 5870 | AC35: =AB35/X35-1 -> -0.18167466 | AF35: =AD35/AB35 -> 0 | AH35: =AH25-AH28 -> 20758.401 | AI35: =AH35/'[2]billing 2022-2025 retrend'!$S$134-1 -> -0.13856623 | AJ35: =F35+O35+Z35 -> 21489.306 | AK35: =AJ35/AH35-1 -> 0.035210107 | AL35: =F35+Q35+AB35 -> 18935.101 | AM35: =AL35/AH35-1 -> -0.087834323 | AP35: =AN35/AJ35 -> 0
B36: 全国不含吴慧玲 | D36: =D24-D28 -> 8834.4771 | E36: ='[1]billing 2022-2025 retrend'!$G$257 -> -0.10748201 | F36: =F24-F28 -> 9220 | G36: =F36/D36-1 -> 0.043638446 | H36: =H24-H28 -> 8177.7095 | I36: =H36/D36-1 -> -0.074341429 | J36: =H36/F36 -> 0.88695331 | K36: 全国不含吴慧玲 | M36: =M24-M28 -> 8500.0033 | N36: ='[1]billing 2022-2025 retrend'!$H$257 -> -0.11786234 | O36: =O24-O28 -> 10213.306 | P36: =O36/M36-1 -> 0.20156497 | Q36: =Q24-Q28 -> 7845.1006 | R36: =Q36/O36-1 -> -0.23187453 | S36: =S24-S28 -> 7538.8139 | T36: =S36/M36-1 -> -0.11308105 | U36: =S36/Q36 -> 0.96095823 | V36: 全国不含吴慧玲 | X36: =X24-X28 -> 8919.56 | Y36: ='[1]billing 2022-2025 retrend'!$I$257 -> -0.14028116 | Z36: 10810 | AA36: =Z36/X36-1 -> 0.21194319 | AB36: =AB24-AB28 -> 7820 | AC36: =AB36/X36-1 -> -0.12327514 | AF36: =AD36/AB36 -> 0 | AH36: =AH24-AH28 -> 26254.04 | AI36: =AH36/'[2]billing 2022-2025 retrend'!$S$136-1 -> -0.12220371 | AJ36: =F36+O36+Z36 -> 30243.306 | AK36: =AJ36/AH36-1 -> 0.15194864 | AL36: =F36+Q36+AB36 -> 24885.101 | AM36: =AL36/AH36-1 -> -0.052142064 | AP36: =AN36/AJ36 -> 0
B40: 开单vs消耗 | D40: 开单/消耗 | F40: 开单/消耗 | H40: 开单/消耗
B41: YesSkin | D41: 2024年4月实际 | F41: 2025年4月指标 | H41: 2025年4月实际（自然月） | K41: YesSkin | M41: 2024年5月实际 | O41: 2025年5月指标 | Q41: 2025年5月指标-0428 | S41: 2025年5月实际（自然月） | V41: YesSkin | X41: 2024年6月实际 | Z41: 2025年6月指标-0326 | AB41: 2025年6月指标-0520 | AD41: 2025 年6月实际（自然月） | AH41: 2024年二季度 | AJ41: 2025年二季度指标-0326 | AL41: 2025年二季度指标-0520 | AN41: 2025年一季度实际
D42: 实际比例 | E42: 增幅 | F42: 指标比例 | G42: 增幅 | H42: 门店实际比例 | I42: 增幅 | M42: 实际比例 | N42: 增幅 | O42: 指标比例 | P42: 增幅 | Q42: 指标比例 | R42: 增幅 | S42: 实际比例 | T42: 增幅 | X42: 实际比例 | Y42: 增幅 | Z42: 指标比例 | AA42: 增幅 | AB42: 指标比例 | AC42: 增幅 | AD42: 门店实际比例 | AE42: 增幅 | AH42: 实际比例 | AI42: 增幅 | AJ42: 指标比例 | AK42: 增幅 | AL42: 指标比例 | AM42: 增幅 | AN42: 门店实际比例 | AO42: 增幅
B43: National Total | D43: =D24/D4 -> 0.96442635 | F43: =F24/F4 -> 0.87936449 | H43: =H24/H4 -> 1.0474002 | K43: National Total | M43: =M24/M4 -> 0.92815483 | O43: =O24/O4 -> 0.9772408 | Q43: =Q24/Q4 -> 0.94857143 | S43: =S24/S4 -> 0.98920498 | V43: National Total | X43: =X24/X4 -> 1.1597868 | AB43: =AB24/AB4 -> 0.94857143 | AH43: =AH24/AH4 -> 1.0089999 | AJ43: =AJ24/AJ4 -> 0.95326439 | AL43: =AL24/AL4 -> 0.92212102
B44: HZ Total | D44: =D25/D5 -> 1.0006197 | F44: =F25/F5 -> 0.86881188 | H44: =H25/H5 -> 1.0165698 | K44: HZ Total | M44: =M25/M5 -> 0.91261055 | O44: =O25/O5 -> 1.0088333 | Q44: =Q25/Q5 -> 0.97841727 | S44: =S25/S5 -> 1.0043804 | V44: HZ Total | X44: =X25/X5 -> 1.2380601 | AB44: =AB25/AB5 -> 0.93382353 | AH44: =AH25/AH5 -> 1.0378271 | AJ44: =AJ25/AJ5 -> 0.95661437 | AL44: =AL25/AL5 -> 0.92395786
B45: 杭州时尚 | C45: HZ Fashion | D45: =D26/D6 -> 0.90746001 | F45: =F26/F6 -> 0.8974359 | H45: =H26/H6 -> 0.96220871 | K45: 杭州时尚 | L45: HZ Fashion | M45: =M26/M6 -> 0.84128981 | O45: =O26/O6 -> 1.0252787 | Q45: =Q26/Q6 -> 1 | S45: =S26/S6 -> 0.93523883 | V45: 杭州时尚 | W45: HZ Fashion | X45: =X26/X6 -> 1.0093632 | AB45: =AB26/AB6 -> 0.92537313 | AH45: =AH26/AH6 -> 0.91876028 | AJ45: =AJ26/AJ6 -> 0.97049586 | AL45: =AL26/AL6 -> 0.93838863
B46: 杭州悦容（西子） | C46: HZ Ruerong | D46: =D27/D7 -> 1.002943 | F46: =F27/F7 -> 0.85185185 | H46: =H27/H7 -> 0.9498754 | K46: 杭州悦容（西子） | L46: HZ Ruerong | M46: =M27/M7 -> 0.99817904 | O46: =O27/O7 -> 1.0496484 | Q46: =Q27/Q7 -> 1 | S46: =S27/S7 -> 0.99623578 | V46: 杭州悦容（西子） | W46: HZ Ruerong | X46: =X27/X7 -> 1.4079707 | AB46: =AB27/AB7 -> 0.93333333 | AH46: =AH27/AH7 -> 1.1090024 | AJ46: =AJ27/AJ7 -> 0.9685561 | AL46: =AL27/AL7 -> 0.9261745
B47: Wu huiling | D47: =D28/D8 -> 1.0093389 | F47: =F28/F8 -> 1 | H47: =H28/H8 -> 0.95154744 | K47: Wu huiling | M47: =M28/M8 -> 1.0323901 | O47: =O28/O8 -> 1 | Q47: =Q28/Q8 -> 1 | S47: =S28/S8 -> 1.0721243 | V47: Wu huiling | X47: =X28/X8 -> 1.085397 | AB47: =AB28/AB8 -> 1 | AH47: =AH28/AH8 -> 1.0383336 | AJ47: =AJ28/AJ8 -> 1 | AL47: =AL28/AL8 -> 1
...

Sheet 2025第三季度指标
B1: 消耗 | H1: 门店按自然月下指标，按自然月考核 | O1: 消耗 | U1: 门店按自然月下指标，按自然月考核
B2: YesSkin | D2: 2024年7月实际 | F2: 2025年7月SRI05 | H2: 2025年7月指标 | J2: 2025年7月实际（自然月） | O2: YesSkin | Q2: 2024年8月实际 | S2: 2025年8月SRI05 | U2: 2025年8月指标 | W2: 2025年8月实际（自然月）
D3: 7月消耗 | E3: 增幅 | F3: 7月消耗 | G3: 增幅 | H3: 7月消耗 | I3: 增幅 | J3: 7月消耗 | K3: Evl% | L3: 指标达成率 | Q3: 8月消耗 | R3: 增幅 | S3: 8月消耗 | T3: 增幅 | U3: 7月消耗 | V3: 增幅 | W3: 7月消耗 | X3: Evl% | Y3: 指标达成率
B4: 全国合计 Total | D4: =D5+D12 -> 6746.5162 | E4: ='[1]consumption-2022-2025 retrend'!$J$246 -> -0.21020031 | F4: =F5+F12 -> 9740.3109 | G4: =F4/D4-1 -> 0.44375415 | H4: =H5+H12 -> 8720 | I4: =H4/D4-1 -> 0.29251894 | K4: =J4/D4-1 -> -1 | L4: =J4/H4 -> 0 | O4: 全国合计 Total | Q4: =Q5+Q12 -> 5046.3487 | R4: ='[1]consumption-2022-2025 retrend'!$K$246 -> -0.33262148 | S4: =S5+S12 -> 9542.2223 | T4: =S4/Q4-1 -> 0.89091616 | U4: =U5+U12 -> 6800 | V4: =U4/Q4-1 -> 0.34750894 | X4: =W4/Q4-1 -> -1 | Y4: =W4/U4 -> 0
B5: 杭州合计 | D5: =D6+D7+D10+D11 -> 5253.9798 | E5: ='[1]consumption-2022-2025 retrend'!$J$222 -> -0.27746654 | F5: =F6+F7+F10+F11 -> 7334.0048 | G5: =F5/D5-1 -> 0.39589513 | H5: =H6+H7+H10+H11 -> 6720 | I5: =H5/D5-1 -> 0.27903042 | K5: =J5/D5-1 -> -1 | L5: =J5/H5 -> 0 | O5: 杭州合计 | Q5: =Q6+Q7+Q10+Q11 -> 4613.6161 | R5: ='[1]consumption-2022-2025 retrend'!$K$222 -> -0.20455406 | S5: =S6+S7+S10+S11 -> 7116.9734 | T5: =S5/Q5-1 -> 0.542602 | U5: =U6+U7+U10+U11 -> 4980 | V5: =U5/Q5-1 -> 0.079413613 | X5: =W5/Q5-1 -> -1 | Y5: =W5/U5 -> 0
B6: 杭州时尚 | C6: HZ Fashion | D6: ='[1]consumption-2022-2025 retrend'!$J$224 -> 2692.0084 | E6: ='[1]consumption-2022-2025 retrend'!$J$225 -> -0.033484248 | F6: ='[2]0503 SRI05V3+PB'!$J$85 -> 3211.5174 | G6: =F6/D6-1 -> 0.19298192 | H6: 3100 | I6: =H6/D6-1 -> 0.15155658 | K6: =J6/D6-1 -> -1 | L6: =J6/H6 -> 0 | O6: 杭州时尚 | P6: HZ Fashion | Q6: ='[1]consumption-2022-2025 retrend'!$K$224 -> 1803.1077 | R6: ='[1]consumption-2022-2025 retrend'!$K$225 -> -0.15183205 | S6: ='[3]0503 SRI05V3+PBV2'!$K$85 -> 2945.918 | T6: =S6/Q6-1 -> 0.63380029 | U6: 2050 | V6: =U6/Q6-1 -> 0.13692596 | X6: =W6/Q6-1 -> -1 | Y6: =W6/U6 -> 0
B7: 杭州悦容（西子） | C7: HZ Ruerong | D7: ='[1]consumption-2022-2025 retrend'!$J$227 -> 1654.4644 | E7: ='[1]consumption-2022-2025 retrend'!$J$228 -> -0.4626619 | F7: ='[2]0503 SRI05V3+PB'!$J$88 -> 2849.0927 | G7: =F7/D7-1 -> 0.72206341 | H7: 2300 | I7: =H7/D7-1 -> 0.39017795 | K7: =J7/D7-1 -> -1 | L7: =J7/H7 -> 0 | O7: 杭州悦容（西子） | P7: HZ Ruerong | Q7: ='[1]consumption-2022-2025 retrend'!$K$227 -> 1896.4678 | R7: ='[1]consumption-2022-2025 retrend'!$K$228 -> -0.35779816 | S7: ='[3]0503 SRI05V3+PBV2'!$K$88 -> 2921.4007 | T7: =S7/Q7-1 -> 0.54044309 | U7: 1850 | V7: =U7/Q7-1 -> -0.024502283 | X7: =W7/Q7-1 -> -1 | Y7: =W7/U7 -> 0
B8: 吴慧玲 | D8: ='[1]consumption-2022-2025 retrend'!$J$250 -> 549.3416 | E8: ='[1]consumption-2022-2025 retrend'!$J$251 -> -0.49323364 | F8: ='[2]0503 SRI05V3+PB'!$K$111 -> 300 | G8: =F8/D8-1 -> -0.45389171 | H8: 400 | O8: 吴慧玲 | Q8: ='[1]consumption-2022-2025 retrend'!$K$250 -> 431.79264 | R8: ='[1]consumption-2022-2025 retrend'!$K$251 -> -0.5861777 | S8: ='[3]0503 SRI05V3+PBV2'!$K$111 -> 300 | T8: =S8/Q8-1 -> -0.30522206 | U8: ='[3]0625 S2 BOTTOM up & 2026 '!$K$111 -> 300
B9: 杭州悦容（西子） 不含吴慧玲 | D9: =D7-D8 -> 1105.1228 | E9: ='[1]consumption-2022-2025 retrend'!$J$253 -> -0.44605017 | F9: =F7-F8 -> 2549.0927 | G9: =F9/D9-1 -> 1.3066148 | H9: =H7-H8 -> 1900 | I9: =H9/D9-1 -> 0.71926587 | K9: =J9/D9-1 -> -1 | L9: =J9/H9 -> 0 | O9: 杭州悦容（西子） 不含吴慧玲 | Q9: =Q7-Q8 -> 1464.6752 | R9: ='[1]consumption-2022-2025 retrend'!$K$253 -> -0.23301222 | S9: =S7-S8 -> 2621.4007 | T9: =S9/Q9-1 -> 0.78974888 | U9: =U7-U8 -> 1550 | V9: =U9/Q9-1 -> 0.058255136 | X9: =W9/Q9-1 -> -1 | Y9: =W9/U9 -> 0
B10: 杭州素颜丰潭（城西） | C10: HZ Suyan Fengtan(West) | D10: ='[1]consumption-2022-2025 retrend'!$J$230 -> 492.86734 | E10: ='[1]consumption-2022-2025 retrend'!$J$231 -> -0.35331299 | F10: ='[2]0503 SRI05V3+PB'!$J$91 -> 512.98611 | G10: =F10/D10-1 -> 0.040819841 | H10: 560 | I10: =H10/D10-1 -> 0.13620838 | K10: =J10/D10-1 -> -1 | L10: =J10/H10 -> 0 | O10: 杭州素颜丰潭（城西） | P10: HZ Suyan Fengtan(West) | Q10: ='[1]consumption-2022-2025 retrend'!$K$230 -> 353.35318 | R10: ='[1]consumption-2022-2025 retrend'!$K$231 -> 0.047960977 | S10: ='[3]0503 SRI05V3+PBV2'!$K$91 -> 526.95178 | T10: =S10/Q10-1 -> 0.4912892 | U10: 450 | V10: =U10/Q10-1 -> 0.27351337 | X10: =W10/Q10-1 -> -1 | Y10: =W10/U10 -> 0
B11: 杭州新芽（万通） | C11: HZ Xinya | D11: ='[1]consumption-2022-2025 retrend'!$J$233 -> 414.63961 | E11: ='[1]consumption-2022-2025 retrend'!$J$234 -> -0.35734084 | F11: ='[2]0503 SRI05V3+PB'!$J$94 -> 760.40867 | G11: =F11/D11-1 -> 0.83390262 | H11: 760 | I11: =H11/D11-1 -> 0.83291702 | K11: =J11/D11-1 -> -1 | L11: =J11/H11 -> 0 | O11: 杭州新芽（万通） | P11: HZ Xinya | Q11: ='[1]consumption-2022-2025 retrend'!$K$233 -> 560.68737 | R11: ='[1]consumption-2022-2025 retrend'!$K$234 -> 0.46050701 | S11: ='[3]0503 SRI05V3+PBV2'!$K$94 -> 722.70297 | T11: =S11/Q11-1 -> 0.28895888 | U11: 630 | V11: =U11/Q11-1 -> 0.12362082 | X11: =W11/Q11-1 -> -1 | Y11: =W11/U11 -> 0
B12: 杭外合计 | D12: =D13+D14 -> 1492.5364 | E12: ='[1]consumption-2022-2025 retrend'!$J$237 -> 0.17480718 | F12: =F13+F14 -> 2406.306 | G12: =F12/D12-1 -> 0.61222598 | H12: =H13+H14 -> 2000 | I12: =H12/D12-1 -> 0.34000079 | K12: =J12/D12-1 -> -1 | L12: =J12/H12 -> 0 | O12: 杭外合计 | Q12: =Q13+Q14 -> 432.73264 | R12: ='[1]consumption-2022-2025 retrend'!$K$237 -> -0.75432626 | S12: =S13+S14 -> 2425.2489 | T12: =S12/Q12-1 -> 4.6044974 | U12: =U13+U14 -> 1820 | V12: =U12/Q12-1 -> 3.2058302 | X12: =W12/Q12-1 -> -1 | Y12: =W12/U12 -> 0
B13: 上海诊所 | C13: SH Clinic | D13: ='[1]consumption-2022-2025 retrend'!$J$239 -> 949.57078 | E13: ='[1]consumption-2022-2025 retrend'!$J$240 -> 0.30360609 | F13: ='[2]0503 SRI05V3+PB'!$J$100 -> 1729.2966 | G13: =F13/D13-1 -> 0.82113499 | H13: 1500 | I13: =H13/D13-1 -> 0.57966108 | K13: =J13/D13-1 -> -1 | L13: =J13/H13 -> 0 | O13: 上海诊所 | P13: SH Clinic | Q13: ='[1]consumption-2022-2025 retrend'!$K$239 -> 89.0132 | R13: ='[1]consumption-2022-2025 retrend'!$K$240 -> -0.92350935 | S13: ='[3]0503 SRI05V3+PBV2'!$K$100 -> 1724.8752 | T13: =S13/Q13-1 -> 18.377747 | U13: 1400 | V13: =U13/Q13-1 -> 14.728004 | X13: =W13/Q13-1 -> -1 | Y13: =W13/U13 -> 0
B14: 苏州诊所 | C14: Suzhuo Clinic | D14: ='[1]consumption-2022-2025 retrend'!$J$242 -> 542.96565 | E14: ='[1]consumption-2022-2025 retrend'!$J$243 -> 0.0017192472 | F14: ='[2]0503 SRI05V3+PB'!$J$103 -> 677.00944 | G14: =F14/D14-1 -> 0.24687343 | H14: 500 | I14: =H14/D14-1 -> -0.079131433 | K14: =J14/D14-1 -> -1 | L14: =J14/H14 -> 0 | O14: 苏州诊所 | P14: Suzhuo Clinic | Q14: ='[1]consumption-2022-2025 retrend'!$K$242 -> 343.71944 | R14: ='[1]consumption-2022-2025 retrend'!$K$243 -> -0.42492822 | S14: ='[3]0503 SRI05V3+PBV2'!$K$103 -> 700.3737 | T14: =S14/Q14-1 -> 1.0376319 | U14: 420 | V14: =U14/Q14-1 -> 0.22192681 | X14: =W14/Q14-1 -> -1 | Y14: =W14/U14 -> 0
B15: 杭州不含吴慧玲 | D15: =D5-D8 -> 4704.6382 | E15: ='[1]consumption-2022-2025 retrend'!$J$255 -> -0.23966599 | F15: =F5-F8 -> 7034.0048 | G15: =F15/D15-1 -> 0.49512131 | H15: =H5-H8 -> 6320 | I15: =H15/D15-1 -> 0.34335515 | K15: =J15/D15-1 -> -1 | L15: =J15/H15 -> 0 | O15: 杭州不含吴慧玲 | Q15: =Q5-Q8 -> 4181.8234 | R15: ='[1]consumption-2022-2025 retrend'!$K$255 -> -0.12083991 | S15: =S5-S8 -> 6816.9734 | T15: =S15/Q15-1 -> 0.63014376 | U15: =U5-U8 -> 4680 | V15: =U15/Q15-1 -> 0.11912903 | X15: =W15/Q15-1 -> -1 | Y15: =W15/U15 -> 0
B16: 全国不含吴慧玲 | D16: =D4-D8 -> 6197.1746 | E16: ='[1]consumption-2022-2025 retrend'!$J$257 -> -0.16906192 | F16: =F4-F8 -> 9440.3109 | G16: =F16/D16-1 -> 0.52332496 | H16: =H4-H8 -> 8320 | I16: =H16/D16-1 -> 0.34254728 | K16: =J16/D16-1 -> -1 | L16: =J16/H16 -> 0 | O16: 全国不含吴慧玲 | Q16: =Q4-Q8 -> 4614.5561 | R16: ='[1]consumption-2022-2025 retrend'!$K$257 -> -0.29203142 | S16: =S4-S8 -> 9242.2223 | T16: =S16/Q16-1 -> 1.002841 | U16: =U4-U8 -> 6500 | V16: =U16/Q16-1 -> 0.4085862 | X16: =W16/Q16-1 -> -1 | Y16: =W16/U16 -> 0
B21: 开单 | H21: 门店按自然月下指标，按自然月考核 | O21: 开单 | U21: 门店按自然月下指标，按自然月考核
B22: YesSkin | D22: 2024年7月实际 | F22: 2025年7月SRI05 | H22: 2025年7月指标 | J22: 2025年7月实际（自然月） | O22: YesSkin | Q22: 2024年8月实际 | S22: 2025年8月SRI05 | U22: 2025年8月指标 | W22: 2025年8月实际（自然月）
D23: 7月开单 | E23: 增幅 | F23: 7月开单 | G23: 增幅 | H23: 7月开单 | I23: 增幅 | J23: 7月开单 | K23: Evl% | L23: 指标达成率 | Q23: 8月开单 | R23: 增幅 | S23: 8月开单 | T23: 增幅 | U23: 7月开单 | V23: 增幅 | W23: 7月开单 | X23: Evl% | Y23: 指标达成率
